<mujoco model="right_schunk_sih_hand-manipulator">
    <actuator>
        <position name="a_th_rot" joint="palm_to_th_proximal" ctrlrange="-1.571 0" kp="200" forcerange="-50 50" />
        <position name="a_th_bend" joint="th_proximal_to_th_inter" ctrlrange="0 1.571" kp="200" forcerange="-50 50" />
        <position name="a_if_bend" joint="palm_to_if_proximal" ctrlrange="-1.571 0" kp="200" forcerange="-50 50" />
        <position name="a_mf_bend" joint="palm_to_mf_proximal" ctrlrange="-1.571 0" kp="200" forcerange="-50 50" />
        <position name="a_rf_lf_bend" joint="palm_to_rf_proximal" ctrlrange="-1.571 0" kp="200" forcerange="-50 50" />
    </actuator>

    
    <asset>
        <mesh file="vive_tracker_0000.stl" name="vive_tracker_vive_tracker" />
    <material name="vive_tracker_htc_vive_blue" specular="0.5" shininess="0.25" rgba="0.698 0.89 1 1" />
        <material name="right_schunk_sih_hand_black" specular="0.5" shininess="0.25" rgba="0.16355 0.16355 0.16355 1" />
        <material name="right_schunk_sih_hand_gray" specular="0.0" shininess="0.25" rgba="0.80848 0.80848 0.80848 1" />
        <material name="right_schunk_sih_hand_brushed_metal" specular="0" shininess="0.25" rgba="0.863 0.863 0.863 1" />
        <material name="right_schunk_sih_hand_screws" specular="0" shininess="0.25" rgba="0.7 0.7 0.7 1" />
        <material name="right_schunk_sih_hand_shiny_metal" specular="0" shininess="0.85" rgba="0.91 0.91 0.98 1" />
        <material name="right_schunk_sih_hand_gold_metal" specular="0" shininess="0.25" rgba="0.917 0.882 0.761 1" />

        <mesh file="palm_0000.stl" name="right_schunk_sih_hand_palm" scale="0.001 0.001 0.001" />
        <mesh file="if_proximal_0000.stl" name="right_schunk_sih_hand_if_proximal" scale="0.001 0.001 0.001" />
        <mesh file="if_distal_0000.stl" name="right_schunk_sih_hand_if_distal" scale="0.001 0.001 0.001" />
        <mesh file="mf_proximal_0000.stl" name="right_schunk_sih_hand_mf_proximal" scale="0.001 0.001 0.001" />
        <mesh file="mf_distal_0000.stl" name="right_schunk_sih_hand_mf_distal" scale="0.001 0.001 0.001" />
        <mesh file="rf_proximal_0000.stl" name="right_schunk_sih_hand_rf_proximal" scale="0.001 0.001 0.001" />
        <mesh file="rf_distal_0000.stl" name="right_schunk_sih_hand_rf_distal" scale="0.001 0.001 0.001" />
        <mesh file="lf_proximal_0000.stl" name="right_schunk_sih_hand_lf_proximal" scale="0.001 0.001 0.001" />
        <mesh file="lf_distal_0000.stl" name="right_schunk_sih_hand_lf_distal" scale="0.001 0.001 0.001" />
        <mesh file="th_proximal_0000.stl" name="right_schunk_sih_hand_th_proximal" scale="0.001 0.001 0.001" />
        <mesh file="th_inter_0000.stl" name="right_schunk_sih_hand_th_inter" scale="0.001 0.001 0.001" />
        <mesh file="th_inter_cvx_0000.stl" name="right_schunk_sih_hand_th_inter_cvx" scale="0.001 0.001 0.001" />
        <mesh file="th_distal_0000.stl" name="right_schunk_sih_hand_th_distal" scale="0.001 0.001 0.001" />

        <mesh file="palm_axes_0000.stl" name="right_schunk_sih_hand_palm_axes" scale="0.001 0.001 0.001" />
        <mesh file="palm_back_base_0000.stl" name="right_schunk_sih_hand_palm_back_base" scale="0.001 0.001 0.001" />
        <mesh file="palm_back_plate_0000.stl" name="right_schunk_sih_hand_palm_back_plate" scale="0.001 0.001 0.001" />
        <mesh file="palm_connector_0000.stl" name="right_schunk_sih_hand_palm_connector" scale="0.001 0.001 0.001" />
        <mesh file="palm_flange_screws_0000.stl" name="right_schunk_sih_hand_palm_flange_screws" scale="0.001 0.001 0.001" />
        <mesh file="palm_flange_0000.stl" name="right_schunk_sih_hand_palm_flange" scale="0.001 0.001 0.001" />
        <mesh file="palm_front_base_0000.stl" name="right_schunk_sih_hand_palm_front_base" scale="0.001 0.001 0.001" />
        <mesh file="palm_front_plate_0000.stl" name="right_schunk_sih_hand_palm_front_plate" scale="0.001 0.001 0.001" />
        <mesh file="palm_pins_0000.stl" name="right_schunk_sih_hand_palm_pins" scale="0.001 0.001 0.001" />
        <mesh file="palm_rolls_0000.stl" name="right_schunk_sih_hand_palm_rolls" scale="0.001 0.001 0.001" />
        <mesh file="palm_springs_0000.stl" name="right_schunk_sih_hand_palm_springs" scale="0.001 0.001 0.001" />
        <mesh file="palm_thumb_base_0000.stl" name="right_schunk_sih_hand_palm_thumb_base" scale="0.001 0.001 0.001" />

        <mesh file="if_distal_top_0000.stl" name="right_schunk_sih_hand_if_distal_top" scale="0.001 0.001 0.001" />
        <mesh file="if_distal_bottom_0000.stl" name="right_schunk_sih_hand_if_distal_bottom" scale="0.001 0.001 0.001" />
        <mesh file="if_distal_nail_0000.stl" name="right_schunk_sih_hand_if_distal_nail" scale="0.001 0.001 0.001" />
        <mesh file="if_distal_axis_0000.stl" name="right_schunk_sih_hand_if_distal_axis" scale="0.001 0.001 0.001" />
        <mesh file="if_distal_spring_0000.stl" name="right_schunk_sih_hand_if_distal_spring" scale="0.001 0.001 0.001" />
        <mesh file="if_proximal_back_plate_0000.stl" name="right_schunk_sih_hand_if_proximal_back_plate" scale="0.001 0.001 0.001" />
        <mesh file="if_proximal_base_0000.stl" name="right_schunk_sih_hand_if_proximal_base" scale="0.001 0.001 0.001" />
        <mesh file="if_proximal_front_plate_0000.stl" name="right_schunk_sih_hand_if_proximal_front_plate" scale="0.001 0.001 0.001" />
        <mesh file="if_proximal_roll_0000.stl" name="right_schunk_sih_hand_if_proximal_roll" scale="0.001 0.001 0.001" />
        <mesh file="if_proximal_screws_0000.stl" name="right_schunk_sih_hand_if_proximal_screws" scale="0.001 0.001 0.001" />

        <mesh file="mf_distal_top_0000.stl" name="right_schunk_sih_hand_mf_distal_top" scale="0.001 0.001 0.001" />
        <mesh file="mf_distal_bottom_0000.stl" name="right_schunk_sih_hand_mf_distal_bottom" scale="0.001 0.001 0.001" />
        <mesh file="mf_distal_nail_0000.stl" name="right_schunk_sih_hand_mf_distal_nail" scale="0.001 0.001 0.001" />
        <mesh file="mf_distal_axis_0000.stl" name="right_schunk_sih_hand_mf_distal_axis" scale="0.001 0.001 0.001" />
        <mesh file="mf_distal_spring_0000.stl" name="right_schunk_sih_hand_mf_distal_spring" scale="0.001 0.001 0.001" />
        <mesh file="mf_proximal_back_plate_0000.stl" name="right_schunk_sih_hand_mf_proximal_back_plate" scale="0.001 0.001 0.001" />
        <mesh file="mf_proximal_base_0000.stl" name="right_schunk_sih_hand_mf_proximal_base" scale="0.001 0.001 0.001" />
        <mesh file="mf_proximal_front_plate_0000.stl" name="right_schunk_sih_hand_mf_proximal_front_plate" scale="0.001 0.001 0.001" />
        <mesh file="mf_proximal_roll_0000.stl" name="right_schunk_sih_hand_mf_proximal_roll" scale="0.001 0.001 0.001" />
        <mesh file="mf_proximal_screws_0000.stl" name="right_schunk_sih_hand_mf_proximal_screws" scale="0.001 0.001 0.001" />

        <mesh file="rf_distal_top_0000.stl" name="right_schunk_sih_hand_rf_distal_top" scale="0.001 0.001 0.001" />
        <mesh file="rf_distal_bottom_0000.stl" name="right_schunk_sih_hand_rf_distal_bottom" scale="0.001 0.001 0.001" />
        <mesh file="rf_distal_nail_0000.stl" name="right_schunk_sih_hand_rf_distal_nail" scale="0.001 0.001 0.001" />
        <mesh file="rf_distal_axis_0000.stl" name="right_schunk_sih_hand_rf_distal_axis" scale="0.001 0.001 0.001" />
        <mesh file="rf_distal_spring_0000.stl" name="right_schunk_sih_hand_rf_distal_spring" scale="0.001 0.001 0.001" />
        <mesh file="rf_proximal_back_plate_0000.stl" name="right_schunk_sih_hand_rf_proximal_back_plate" scale="0.001 0.001 0.001" />
        <mesh file="rf_proximal_base_0000.stl" name="right_schunk_sih_hand_rf_proximal_base" scale="0.001 0.001 0.001" />
        <mesh file="rf_proximal_front_plate_0000.stl" name="right_schunk_sih_hand_rf_proximal_front_plate" scale="0.001 0.001 0.001" />
        <mesh file="rf_proximal_roll_0000.stl" name="right_schunk_sih_hand_rf_proximal_roll" scale="0.001 0.001 0.001" />
        <mesh file="rf_proximal_screws_0000.stl" name="right_schunk_sih_hand_rf_proximal_screws" scale="0.001 0.001 0.001" />

        <mesh file="lf_distal_top_0000.stl" name="right_schunk_sih_hand_lf_distal_top" scale="0.001 0.001 0.001" />
        <mesh file="lf_distal_bottom_0000.stl" name="right_schunk_sih_hand_lf_distal_bottom" scale="0.001 0.001 0.001" />
        <mesh file="lf_distal_nail_0000.stl" name="right_schunk_sih_hand_lf_distal_nail" scale="0.001 0.001 0.001" />
        <mesh file="lf_proximal_axis_0000.stl" name="right_schunk_sih_hand_lf_proximal_axis" scale="0.001 0.001 0.001" />
        <mesh file="lf_proximal_back_plate_0000.stl" name="right_schunk_sih_hand_lf_proximal_back_plate" scale="0.001 0.001 0.001" />
        <mesh file="lf_proximal_base_0000.stl" name="right_schunk_sih_hand_lf_proximal_base" scale="0.001 0.001 0.001" />
        <mesh file="lf_proximal_front_plate_0000.stl" name="right_schunk_sih_hand_lf_proximal_front_plate" scale="0.001 0.001 0.001" />
        <mesh file="lf_proximal_roll_0000.stl" name="right_schunk_sih_hand_lf_proximal_roll" scale="0.001 0.001 0.001" />
        <mesh file="lf_proximal_screws_0000.stl" name="right_schunk_sih_hand_lf_proximal_screws" scale="0.001 0.001 0.001" />

        <mesh file="th_distal_top_0000.stl" name="right_schunk_sih_hand_th_distal_top" scale="0.001 0.001 0.001" />
        <mesh file="th_distal_bottom_0000.stl" name="right_schunk_sih_hand_th_distal_bottom" scale="0.001 0.001 0.001" />
        <mesh file="th_distal_nail_0000.stl" name="right_schunk_sih_hand_th_distal_nail" scale="0.001 0.001 0.001" />
        <mesh file="th_distal_axis_0000.stl" name="right_schunk_sih_hand_th_distal_axis" scale="0.001 0.001 0.001" />

        <mesh file="th_inter_back_plate_0000.stl" name="right_schunk_sih_hand_th_inter_back_plate" scale="0.001 0.001 0.001" />
        <mesh file="th_inter_base_0000.stl" name="right_schunk_sih_hand_th_inter_base" scale="0.001 0.001 0.001" />
        <mesh file="th_inter_front_plate_0000.stl" name="right_schunk_sih_hand_th_inter_front_plate" scale="0.001 0.001 0.001" />
        <mesh file="th_inter_roll_0000.stl" name="right_schunk_sih_hand_th_inter_roll" scale="0.001 0.001 0.001" />
        <mesh file="th_inter_screws_0000.stl" name="right_schunk_sih_hand_th_inter_screws" scale="0.001 0.001 0.001" />
        <mesh file="th_inter_spring_0000.stl" name="right_schunk_sih_hand_th_inter_spring" scale="0.001 0.001 0.001" />

        <mesh file="th_proximal_axis_0000.stl" name="right_schunk_sih_hand_th_proximal_axis" scale="0.001 0.001 0.001" />
        <mesh file="th_proximal_base_0000.stl" name="right_schunk_sih_hand_th_proximal_base" scale="0.001 0.001 0.001" />
        <mesh file="th_proximal_guides_0000.stl" name="right_schunk_sih_hand_th_proximal_guides" scale="0.001 0.001 0.001" />
        <mesh file="th_proximal_roll_0000.stl" name="right_schunk_sih_hand_th_proximal_roll" scale="0.001 0.001 0.001" />
        <mesh file="th_proximal_screws_0000.stl" name="right_schunk_sih_hand_th_proximal_screws" scale="0.001 0.001 0.001" />
        <mesh file="th_proximal_spring_0000.stl" name="right_schunk_sih_hand_th_proximal_spring" scale="0.001 0.001 0.001" />

    </asset>

    <compiler angle="radian" meshdir=".dexterity_xml_model_meshes" autolimits="true" />

    <contact>
        <exclude body1="if_proximal" body2="if_distal" />
        <exclude body1="mf_proximal" body2="mf_distal" />
        <exclude body1="rf_proximal" body2="rf_distal" />
        <exclude body1="lf_proximal" body2="lf_distal" />
        <exclude body1="th_proximal" body2="th_distal" />

        <exclude body1="palm" body2="if_proximal" />
        <exclude body1="palm" body2="mf_proximal" />
        <exclude body1="palm" body2="rf_proximal" />
        <exclude body1="palm" body2="lf_proximal" />
        <exclude body1="palm" body2="th_proximal" />
    </contact>

    <default /><equality>
        <joint name="th_bend_equality" joint1="th_proximal_to_th_inter" joint2="th_inter_to_th_distal" polycoef="0 1 0 0 0" />
        <joint name="if_bend_equality" joint1="palm_to_if_proximal" joint2="if_proximal_to_if_distal" polycoef="0 1 0 0 0" />
        <joint name="mf_bend_equality" joint1="palm_to_mf_proximal" joint2="mf_proximal_to_mf_distal" polycoef="0 1 0 0 0" />
        <joint name="rf_bend_equality" joint1="palm_to_rf_proximal" joint2="rf_proximal_to_rf_distal" polycoef="0 1 0 0 0" />
        <joint name="rf_lf_equality1" joint1="palm_to_rf_proximal" joint2="palm_to_lf_proximal" polycoef="0 1 0 0 0" />
        <joint name="rf_lf_equality2" joint1="palm_to_rf_proximal" joint2="lf_proximal_to_lf_distal" polycoef="0 1 0 0 0" />
    <weld body1="__mocap__" body2="tracker" solimp="0.9 0.95 0.001" solref="0.02 1" /></equality>

    <keyframe>
        <key name="home" qpos="0 0 0 1 0 0 0 0 0 0 0 0 0 0 0 0 0 0" ctrl="0 0 0 0 0" />
        <key name="initial" qpos="0 0 0 1 0 0 0 0 0 0 0 0 0 0 0 0 0 0" ctrl="0 0 0 0 0" />
    </keyframe>
<sensor /><worldbody>
            <body name="palm" pos="0. 0.025 0.042" quat="0.707 0.707 0 0">
                
                <body name="tracker" quat="-0.5 -0.5 0.5 -0.5" pos=" 0.   -0.04  0.08">
            <geom mesh="vive_tracker_vive_tracker" material="vive_tracker_htc_vive_blue" quat="0.5 0.5 -0.5 -0.5" type="mesh" contype="0" conaffinity="0" group="2" />
        </body>
    <site name="vive_tracker_attached_here" pos="0 -0.04 0.08" quat="0 0 0 -1" />
                <geom type="mesh" mesh="right_schunk_sih_hand_palm_axes" material="right_schunk_sih_hand_shiny_metal" contype="0" conaffinity="0" group="2" solimp="0.5 0.99 0.0001" solref="0.005 1" />
                <geom type="mesh" mesh="right_schunk_sih_hand_palm_back_base" material="right_schunk_sih_hand_black" contype="0" conaffinity="0" group="2" solimp="0.5 0.99 0.0001" solref="0.005 1" />
                <geom type="mesh" mesh="right_schunk_sih_hand_palm_back_plate" material="right_schunk_sih_hand_black" contype="0" conaffinity="0" group="2" solimp="0.5 0.99 0.0001" solref="0.005 1" />
                <geom type="mesh" mesh="right_schunk_sih_hand_palm_connector" material="right_schunk_sih_hand_gold_metal" contype="0" conaffinity="0" group="2" solimp="0.5 0.99 0.0001" solref="0.005 1" />
                <geom type="mesh" mesh="right_schunk_sih_hand_palm_flange_screws" material="right_schunk_sih_hand_screws" contype="0" conaffinity="0" group="2" solimp="0.5 0.99 0.0001" solref="0.005 1" />
                <geom type="mesh" mesh="right_schunk_sih_hand_palm_flange" material="right_schunk_sih_hand_brushed_metal" contype="0" conaffinity="0" group="2" solimp="0.5 0.99 0.0001" solref="0.005 1" />
                <geom type="mesh" mesh="right_schunk_sih_hand_palm_front_base" material="right_schunk_sih_hand_brushed_metal" contype="0" conaffinity="0" group="2" solimp="0.5 0.99 0.0001" solref="0.005 1" />
                <geom type="mesh" mesh="right_schunk_sih_hand_palm_front_plate" material="right_schunk_sih_hand_black" contype="0" conaffinity="0" group="2" solimp="0.5 0.99 0.0001" solref="0.005 1" />
                <geom type="mesh" mesh="right_schunk_sih_hand_palm_pins" material="right_schunk_sih_hand_shiny_metal" contype="0" conaffinity="0" group="2" solimp="0.5 0.99 0.0001" solref="0.005 1" />
                <geom type="mesh" mesh="right_schunk_sih_hand_palm_rolls" material="right_schunk_sih_hand_screws" contype="0" conaffinity="0" group="2" solimp="0.5 0.99 0.0001" solref="0.005 1" />
                <geom type="mesh" mesh="right_schunk_sih_hand_palm_springs" material="right_schunk_sih_hand_screws" contype="0" conaffinity="0" group="2" solimp="0.5 0.99 0.0001" solref="0.005 1" />
                <geom type="mesh" mesh="right_schunk_sih_hand_palm_thumb_base" material="right_schunk_sih_hand_brushed_metal" contype="0" conaffinity="0" group="2" solimp="0.5 0.99 0.0001" solref="0.005 1" />
                <geom type="mesh" mesh="right_schunk_sih_hand_palm" group="3" material="right_schunk_sih_hand_gray" solimp="0.5 0.99 0.0001" solref="0.005 1" />

                
                <site name="keypoint-hand_bodies-palm" pos="0 0.018 0.09" />

                
                <body name="if_proximal" pos="0.0435 0 0.141">
                    <site name="keypoint-hand_bodies-if_proximal" pos="-0.087 0.016 0.022" />
                    <site name="teleop-rh_if_flexion" user="0 -1.571 0 0 0" />
                    
                    <joint name="palm_to_if_proximal" range="-1.571 0" pos="0 0 0" axis="1 0 0" damping="1" armature="0.01" limited="true" />
                    <geom pos="-0.0435 0 -0.141" type="mesh" mesh="right_schunk_sih_hand_if_proximal_back_plate" material="right_schunk_sih_hand_black" contype="0" conaffinity="0" group="2" solimp="0.5 0.99 0.0001" solref="0.005 1" />
                    <geom pos="-0.0435 0 -0.141" type="mesh" mesh="right_schunk_sih_hand_if_proximal_base" material="right_schunk_sih_hand_brushed_metal" contype="0" conaffinity="0" group="2" solimp="0.5 0.99 0.0001" solref="0.005 1" />
                    <geom pos="-0.0435 0 -0.141" type="mesh" mesh="right_schunk_sih_hand_if_proximal_front_plate" material="right_schunk_sih_hand_black" contype="0" conaffinity="0" group="2" solimp="0.5 0.99 0.0001" solref="0.005 1" />
                    <geom pos="-0.0435 0 -0.141" type="mesh" mesh="right_schunk_sih_hand_if_proximal_roll" material="right_schunk_sih_hand_screws" contype="0" conaffinity="0" group="2" solimp="0.5 0.99 0.0001" solref="0.005 1" />
                    <geom pos="-0.0435 0 -0.141" type="mesh" mesh="right_schunk_sih_hand_if_proximal_screws" material="right_schunk_sih_hand_screws" contype="0" conaffinity="0" group="2" solimp="0.5 0.99 0.0001" solref="0.005 1" />
                    <geom pos="-0.0435 0 -0.141" type="mesh" mesh="right_schunk_sih_hand_if_proximal" group="3" material="right_schunk_sih_hand_gray" solimp="0.5 0.99 0.0001" solref="0.005 1" />
                    <body name="if_distal" pos="0 0 0.048">
                        <site name="keypoint-hand_bodies-if_distal" pos="-0.087 0.0175 0.041" />
                        <site name="keypoint-fingertips-if" pos="-0.087 0.0175 0.041" />
                        
                        <joint name="if_proximal_to_if_distal" range="-1.571 0" pos="0 0 0" axis="1 0 0" damping="1" armature="0.01" limited="true" />
                        <geom pos="-0.0435 0 -0.189" type="mesh" mesh="right_schunk_sih_hand_if_distal_top" material="right_schunk_sih_hand_black" contype="0" conaffinity="0" group="2" solimp="0.5 0.99 0.0001" solref="0.005 1" />
                        <geom pos="-0.0435 0 -0.189" type="mesh" mesh="right_schunk_sih_hand_if_distal_bottom" material="right_schunk_sih_hand_brushed_metal" contype="0" conaffinity="0" group="2" solimp="0.5 0.99 0.0001" solref="0.005 1" />
                        <geom pos="-0.0435 0 -0.189" type="mesh" mesh="right_schunk_sih_hand_if_distal_nail" material="right_schunk_sih_hand_black" contype="0" conaffinity="0" group="2" solimp="0.5 0.99 0.0001" solref="0.005 1" />
                        <geom pos="-0.0435 0 -0.189" type="mesh" mesh="right_schunk_sih_hand_if_distal_axis" material="right_schunk_sih_hand_shiny_metal" contype="0" conaffinity="0" group="2" solimp="0.5 0.99 0.0001" solref="0.005 1" />
                        <geom pos="-0.0435 0 -0.189" type="mesh" mesh="right_schunk_sih_hand_if_distal_spring" material="right_schunk_sih_hand_screws" contype="0" conaffinity="0" group="2" solimp="0.5 0.99 0.0001" solref="0.005 1" />
                        <geom pos="-0.0435 0 -0.189" type="mesh" mesh="right_schunk_sih_hand_if_distal" group="3" material="right_schunk_sih_hand_gray" solimp="0.5 0.99 0.0001" solref="0.005 1" />
                    </body>
                </body>

                
                <body name="mf_proximal" pos="0.0187 0 0.141">
                    <site name="keypoint-hand_bodies-mf_proximal" pos="-0.0375 0.016 0.024" />
                    <site name="teleop-rh_mf_flexion" user="0 -1.571 0 0 0" />
                    
                    <joint name="palm_to_mf_proximal" range="-1.571 0" pos="0 0 0" axis="1 0 0" damping="1" armature="0.01" limited="true" />
                    <geom pos="-0.0187 0 -0.141" type="mesh" mesh="right_schunk_sih_hand_mf_proximal_back_plate" material="right_schunk_sih_hand_black" contype="0" conaffinity="0" group="2" solimp="0.5 0.99 0.0001" solref="0.005 1" />
                    <geom pos="-0.0187 0 -0.141" type="mesh" mesh="right_schunk_sih_hand_mf_proximal_base" material="right_schunk_sih_hand_brushed_metal" contype="0" conaffinity="0" group="2" solimp="0.5 0.99 0.0001" solref="0.005 1" />
                    <geom pos="-0.0187 0 -0.141" type="mesh" mesh="right_schunk_sih_hand_mf_proximal_front_plate" material="right_schunk_sih_hand_black" contype="0" conaffinity="0" group="2" solimp="0.5 0.99 0.0001" solref="0.005 1" />
                    <geom pos="-0.0187 0 -0.141" type="mesh" mesh="right_schunk_sih_hand_mf_proximal_roll" material="right_schunk_sih_hand_screws" contype="0" conaffinity="0" group="2" solimp="0.5 0.99 0.0001" solref="0.005 1" />
                    <geom pos="-0.0187 0 -0.141" type="mesh" mesh="right_schunk_sih_hand_mf_proximal_screws" material="right_schunk_sih_hand_screws" contype="0" conaffinity="0" group="2" solimp="0.5 0.99 0.0001" solref="0.005 1" />
                    <geom pos="-0.0187 0 -0.141" type="mesh" mesh="right_schunk_sih_hand_mf_proximal" group="3" material="right_schunk_sih_hand_gray" solimp="0.5 0.99 0.0001" solref="0.005 1" />
                    <body name="mf_distal" pos="0 0 0.0525">
                        <site name="keypoint-hand_bodies-mf_distal" pos="-0.0375 0.0175 0.049" />
                        <site name="keypoint-fingertips-mf" pos="-0.0375 0.0175 0.049" />
                        
                        <joint name="mf_proximal_to_mf_distal" range="-1.571 0" pos="0 0 0" axis="1 0 0" damping="1" armature="0.01" limited="true" />
                        <geom pos="-0.0187 0 -0.1935" type="mesh" mesh="right_schunk_sih_hand_mf_distal_top" material="right_schunk_sih_hand_black" contype="0" conaffinity="0" group="2" solimp="0.5 0.99 0.0001" solref="0.005 1" />
                        <geom pos="-0.0187 0 -0.1935" type="mesh" mesh="right_schunk_sih_hand_mf_distal_bottom" material="right_schunk_sih_hand_brushed_metal" contype="0" conaffinity="0" group="2" solimp="0.5 0.99 0.0001" solref="0.005 1" />
                        <geom pos="-0.0187 0 -0.1935" type="mesh" mesh="right_schunk_sih_hand_mf_distal_nail" material="right_schunk_sih_hand_black" contype="0" conaffinity="0" group="2" solimp="0.5 0.99 0.0001" solref="0.005 1" />
                        <geom pos="-0.0187 0 -0.1935" type="mesh" mesh="right_schunk_sih_hand_mf_distal_axis" material="right_schunk_sih_hand_shiny_metal" contype="0" conaffinity="0" group="2" solimp="0.5 0.99 0.0001" solref="0.005 1" />
                        <geom pos="-0.0187 0 -0.1935" type="mesh" mesh="right_schunk_sih_hand_mf_distal_spring" material="right_schunk_sih_hand_screws" contype="0" conaffinity="0" group="2" solimp="0.5 0.99 0.0001" solref="0.005 1" />
                        <geom pos="-0.0187 0 -0.1935" type="mesh" mesh="right_schunk_sih_hand_mf_distal" group="3" material="right_schunk_sih_hand_gray" solimp="0.5 0.99 0.0001" solref="0.005 1" />
                    </body>
                </body>

                
                <body name="rf_proximal" pos="-0.0069 0 0.134">
                    <site name="keypoint-hand_bodies-rf_proximal" pos="0.014 0.016 0.0215" />
                    <site name="teleop-rh_rf_flexion" user="0 -1.571 0 0 0" />
                    
                    <joint name="palm_to_rf_proximal" range="-1.571 0" pos="0 0 0" axis="1 0 0" damping="1" armature="0.01" limited="true" />
                    <geom pos="0.0069 0 -0.134" type="mesh" mesh="right_schunk_sih_hand_rf_proximal_back_plate" material="right_schunk_sih_hand_black" contype="0" conaffinity="0" group="2" solimp="0.5 0.99 0.0001" solref="0.005 1" />
                    <geom pos="0.0069 0 -0.134" type="mesh" mesh="right_schunk_sih_hand_rf_proximal_base" material="right_schunk_sih_hand_brushed_metal" contype="0" conaffinity="0" group="2" solimp="0.5 0.99 0.0001" solref="0.005 1" />
                    <geom pos="0.0069 0 -0.134" type="mesh" mesh="right_schunk_sih_hand_rf_proximal_front_plate" material="right_schunk_sih_hand_black" contype="0" conaffinity="0" group="2" solimp="0.5 0.99 0.0001" solref="0.005 1" />
                    <geom pos="0.0069 0 -0.134" type="mesh" mesh="right_schunk_sih_hand_rf_proximal_roll" material="right_schunk_sih_hand_screws" contype="0" conaffinity="0" group="2" solimp="0.5 0.99 0.0001" solref="0.005 1" />
                    <geom pos="0.0069 0 -0.134" type="mesh" mesh="right_schunk_sih_hand_rf_proximal_screws" material="right_schunk_sih_hand_screws" contype="0" conaffinity="0" group="2" solimp="0.5 0.99 0.0001" solref="0.005 1" />
                    <geom pos="0.0069 0 -0.134" type="mesh" mesh="right_schunk_sih_hand_rf_proximal" group="3" material="right_schunk_sih_hand_gray" solimp="0.5 0.99 0.0001" solref="0.005 1" />
                    <body name="rf_distal" pos="0 0 0.048">
                        <site name="keypoint-hand_bodies-rf_distal" pos="0.014 0.0175 0.041" />
                        <site name="keypoint-fingertips-rf" pos="0.014 0.0175 0.041" />
                        
                        <joint name="rf_proximal_to_rf_distal" range="-1.571 0" pos="0 0 0" axis="1 0 0" damping="1" armature="0.01" limited="true" />
                        <geom pos="0.0069 0 -0.182" type="mesh" mesh="right_schunk_sih_hand_rf_distal_top" material="right_schunk_sih_hand_black" contype="0" conaffinity="0" group="2" solimp="0.5 0.99 0.0001" solref="0.005 1" />
                        <geom pos="0.0069 0 -0.182" type="mesh" mesh="right_schunk_sih_hand_rf_distal_bottom" material="right_schunk_sih_hand_brushed_metal" contype="0" conaffinity="0" group="2" solimp="0.5 0.99 0.0001" solref="0.005 1" />
                        <geom pos="0.0069 0 -0.182" type="mesh" mesh="right_schunk_sih_hand_rf_distal_nail" material="right_schunk_sih_hand_black" contype="0" conaffinity="0" group="2" solimp="0.5 0.99 0.0001" solref="0.005 1" />
                        <geom pos="0.0069 0 -0.182" type="mesh" mesh="right_schunk_sih_hand_rf_distal_axis" material="right_schunk_sih_hand_shiny_metal" contype="0" conaffinity="0" group="2" solimp="0.5 0.99 0.0001" solref="0.005 1" />
                        <geom pos="0.0069 0 -0.182" type="mesh" mesh="right_schunk_sih_hand_rf_distal_spring" material="right_schunk_sih_hand_screws" contype="0" conaffinity="0" group="2" solimp="0.5 0.99 0.0001" solref="0.005 1" />
                        <geom pos="0.0069 0 -0.182" type="mesh" mesh="right_schunk_sih_hand_rf_distal" group="3" material="right_schunk_sih_hand_gray" solimp="0.5 0.99 0.0001" solref="0.005 1" />
                    </body>
                </body>

                
                <body name="lf_proximal" pos="-0.032 0 0.1254">
                    <site name="keypoint-hand_bodies-lf_proximal" pos="0.064 0.016 0.01685" />
                    
                    <joint name="palm_to_lf_proximal" range="-1.571 0" pos="0 0 0" axis="1 0 0" damping="1" armature="0.01" limited="true" />
                    <geom pos="0.032 0 -0.1254" type="mesh" mesh="right_schunk_sih_hand_lf_proximal_axis" material="right_schunk_sih_hand_shiny_metal" contype="0" conaffinity="0" group="2" solimp="0.5 0.99 0.0001" solref="0.005 1" />
                    <geom pos="0.032 0 -0.1254" type="mesh" mesh="right_schunk_sih_hand_lf_proximal_back_plate" material="right_schunk_sih_hand_black" contype="0" conaffinity="0" group="2" solimp="0.5 0.99 0.0001" solref="0.005 1" />
                    <geom pos="0.032 0 -0.1254" type="mesh" mesh="right_schunk_sih_hand_lf_proximal_base" material="right_schunk_sih_hand_brushed_metal" contype="0" conaffinity="0" group="2" solimp="0.5 0.99 0.0001" solref="0.005 1" />
                    <geom pos="0.032 0 -0.1254" type="mesh" mesh="right_schunk_sih_hand_lf_proximal_front_plate" material="right_schunk_sih_hand_black" contype="0" conaffinity="0" group="2" solimp="0.5 0.99 0.0001" solref="0.005 1" />
                    <geom pos="0.032 0 -0.1254" type="mesh" mesh="right_schunk_sih_hand_lf_proximal_roll" material="right_schunk_sih_hand_screws" contype="0" conaffinity="0" group="2" solimp="0.5 0.99 0.0001" solref="0.005 1" />
                    <geom pos="0.032 0 -0.1254" type="mesh" mesh="right_schunk_sih_hand_lf_proximal_screws" material="right_schunk_sih_hand_screws" contype="0" conaffinity="0" group="2" solimp="0.5 0.99 0.0001" solref="0.005 1" />
                    <geom pos="0.032 0 -0.1254" type="mesh" mesh="right_schunk_sih_hand_lf_proximal" group="3" material="right_schunk_sih_hand_gray" solimp="0.5 0.99 0.0001" solref="0.005 1" />
                    <body name="lf_distal" pos="0 0 0.0401">
                        <site name="keypoint-hand_bodies-lf_distal" pos="0.064 0.0175 0.034" />
                        <site name="keypoint-fingertips-lf" pos="0.064 0.0175 0.034" />
                        
                        <joint name="lf_proximal_to_lf_distal" range="-1.571 0" pos="0 0 0" axis="1 0 0" damping="1" armature="0.01" limited="true" />
                        <geom pos="0.032 0 -0.1655" type="mesh" mesh="right_schunk_sih_hand_lf_distal_top" material="right_schunk_sih_hand_black" contype="0" conaffinity="0" group="2" solimp="0.5 0.99 0.0001" solref="0.005 1" />
                        <geom pos="0.032 0 -0.1655" type="mesh" mesh="right_schunk_sih_hand_lf_distal_bottom" material="right_schunk_sih_hand_brushed_metal" contype="0" conaffinity="0" group="2" solimp="0.5 0.99 0.0001" solref="0.005 1" />
                        <geom pos="0.032 0 -0.1655" type="mesh" mesh="right_schunk_sih_hand_lf_distal_nail" material="right_schunk_sih_hand_black" contype="0" conaffinity="0" group="2" solimp="0.5 0.99 0.0001" solref="0.005 1" />
                        <geom pos="0.032 0 -0.1655" type="mesh" mesh="right_schunk_sih_hand_lf_distal" group="3" material="right_schunk_sih_hand_gray" solimp="0.5 0.99 0.0001" solref="0.005 1" />
                    </body>
                </body>

                
                <body name="th_proximal" pos="-0.034 0.019 0.08">
                    <site name="teleop-rh_th_angle0" user="-1.571 -1 0 0 0" />
                    <site name="keypoint-hand_bodies-th_proximal" pos="-0.0115 0.005 0.011" />
                    
                    <joint name="palm_to_th_proximal" range="-1.571 0" pos="0 0 0" axis="0 0 1" damping="1" armature="0.01" limited="true" />
                    <geom pos="0.034 -0.019 -0.08" type="mesh" mesh="right_schunk_sih_hand_th_proximal_axis" material="right_schunk_sih_hand_shiny_metal" contype="0" conaffinity="0" group="2" solimp="0.5 0.99 0.0001" solref="0.005 1" />
                    <geom pos="0.034 -0.019 -0.08" type="mesh" mesh="right_schunk_sih_hand_th_proximal_base" material="right_schunk_sih_hand_brushed_metal" contype="0" conaffinity="0" group="2" solimp="0.5 0.99 0.0001" solref="0.005 1" />
                    <geom pos="0.034 -0.019 -0.08" type="mesh" mesh="right_schunk_sih_hand_th_proximal_guides" material="right_schunk_sih_hand_black" contype="0" conaffinity="0" group="2" solimp="0.5 0.99 0.0001" solref="0.005 1" />
                    <geom pos="0.034 -0.019 -0.08" type="mesh" mesh="right_schunk_sih_hand_th_proximal_roll" material="right_schunk_sih_hand_screws" contype="0" conaffinity="0" group="2" solimp="0.5 0.99 0.0001" solref="0.005 1" />
                    <geom pos="0.034 -0.019 -0.08" type="mesh" mesh="right_schunk_sih_hand_th_proximal_screws" material="right_schunk_sih_hand_screws" contype="0" conaffinity="0" group="2" solimp="0.5 0.99 0.0001" solref="0.005 1" />
                    <geom pos="0.034 -0.019 -0.08" type="mesh" mesh="right_schunk_sih_hand_th_proximal_spring" material="right_schunk_sih_hand_screws" contype="0" conaffinity="0" group="2" solimp="0.5 0.99 0.0001" solref="0.005 1" />
                    <geom pos="0.034 -0.019 -0.08" type="mesh" mesh="right_schunk_sih_hand_th_proximal" group="3" material="right_schunk_sih_hand_gray" solimp="0.5 0.99 0.0001" solref="0.005 1" />
                    <body name="th_inter" pos="-0.024 0.005 0.001">
                        <site name="teleop-rh_th_flexion" user="0 1.571 0 0 0" />
                        <site name="keypoint-hand_bodies-th_inter" pos="-0.0175 0 0.016" />
                        
                        <joint name="th_proximal_to_th_inter" range="0 1.571" pos="0 0 0" axis="0 1 0" damping="1" armature="0.01" limited="true" />
                        <geom pos="0.058 -0.024 -0.081" type="mesh" mesh="right_schunk_sih_hand_th_inter_back_plate" material="right_schunk_sih_hand_black" contype="0" conaffinity="0" group="2" solimp="0.5 0.99 0.0001" solref="0.005 1" />
                        <geom pos="0.058 -0.024 -0.081" type="mesh" mesh="right_schunk_sih_hand_th_inter_base" material="right_schunk_sih_hand_brushed_metal" contype="0" conaffinity="0" group="2" solimp="0.5 0.99 0.0001" solref="0.005 1" />
                        <geom pos="0.058 -0.024 -0.081" type="mesh" mesh="right_schunk_sih_hand_th_inter_front_plate" material="right_schunk_sih_hand_black" contype="0" conaffinity="0" group="2" solimp="0.5 0.99 0.0001" solref="0.005 1" />
                        <geom pos="0.058 -0.024 -0.081" type="mesh" mesh="right_schunk_sih_hand_th_inter_roll" material="right_schunk_sih_hand_screws" contype="0" conaffinity="0" group="2" solimp="0.5 0.99 0.0001" solref="0.005 1" />
                        <geom pos="0.058 -0.024 -0.081" type="mesh" mesh="right_schunk_sih_hand_th_inter_screws" material="right_schunk_sih_hand_screws" contype="0" conaffinity="0" group="2" solimp="0.5 0.99 0.0001" solref="0.005 1" />
                        <geom pos="0.058 -0.024 -0.081" type="mesh" mesh="right_schunk_sih_hand_th_inter_spring" material="right_schunk_sih_hand_screws" contype="0" conaffinity="0" group="2" solimp="0.5 0.99 0.0001" solref="0.005 1" />
                        <geom pos="0.058 -0.024 -0.081" type="mesh" mesh="right_schunk_sih_hand_th_inter_cvx" group="3" material="right_schunk_sih_hand_gray" solimp="0.5 0.99 0.0001" solref="0.005 1" />
                        <body name="th_distal" pos="-0.0391 0 0">
                            <site name="keypoint-hand_bodies-th_distal" pos="-0.023 0 0.015" />
                            <site name="keypoint-fingertips-th" pos="-0.023 0 0.015" />
                            
                            <joint name="th_inter_to_th_distal" range="0 1.571" pos="0 0 0" axis="0 1 0" damping="1" armature="0.01" limited="true" />
                            <geom pos="0.0971 -0.024 -0.081" type="mesh" mesh="right_schunk_sih_hand_th_distal_top" material="right_schunk_sih_hand_black" contype="0" conaffinity="0" group="2" solimp="0.5 0.99 0.0001" solref="0.005 1" />
                            <geom pos="0.0971 -0.024 -0.081" type="mesh" mesh="right_schunk_sih_hand_th_distal_bottom" material="right_schunk_sih_hand_brushed_metal" contype="0" conaffinity="0" group="2" solimp="0.5 0.99 0.0001" solref="0.005 1" />
                            <geom pos="0.0971 -0.024 -0.081" type="mesh" mesh="right_schunk_sih_hand_th_distal_nail" material="right_schunk_sih_hand_black" contype="0" conaffinity="0" group="2" solimp="0.5 0.99 0.0001" solref="0.005 1" />
                            <geom pos="0.0971 -0.024 -0.081" type="mesh" mesh="right_schunk_sih_hand_th_distal_axis" material="right_schunk_sih_hand_shiny_metal" contype="0" conaffinity="0" group="2" solimp="0.5 0.99 0.0001" solref="0.005 1" />
                            <geom pos="0.0971 -0.024 -0.081" type="mesh" mesh="right_schunk_sih_hand_th_distal" group="3" material="right_schunk_sih_hand_gray" solimp="0.5 0.99 0.0001" solref="0.005 1" />
                        </body>
                    </body>
                </body>
            <freejoint /></body>
    <site name="canonical_keypoint_pos0" rgba="1 0 0 1" pos="-0.18715273 -0.02266804 -0.10838989" /><site name="canonical_keypoint_pos1" rgba="1 0 0 1" pos="-0.14178318 -0.01370829 -0.05954232" /><site name="canonical_keypoint_pos2" rgba="1 0 0 1" pos="-0.14404717  0.02866638 -0.06231225" /><site name="canonical_keypoint_pos3" rgba="1 0 0 1" pos="-0.14765655 -0.01460706 -0.08512168" /><site name="canonical_keypoint_pos4" rgba="1 0 0 1" pos="-0.17425147  0.01824964 -0.09027169" /><site name="canonical_keypoint_pos5" rgba="1 0 0 1" pos="-0.14981426 -0.0174016  -0.111351  " /><site name="canonical_keypoint_pos6" rgba="1 0 0 1" pos="-0.16622141  0.01580457 -0.11529016" /><site name="canonical_keypoint_pos7" rgba="1 0 0 1" pos="-0.15537076 -0.02205938 -0.13687229" /><site name="canonical_keypoint_pos8" rgba="1 0 0 1" pos="-0.1652428   0.00592306 -0.13971385" /><site name="canonical_keypoint_pos9" rgba="1 0 0 1" pos="-0.18952511 -0.00722147 -0.07430357" /><site name="canonical_keypoint_pos10" rgba="1 0 0 1" pos="-0.17643553  0.00765693 -0.06547982" /><site name="canonical_keypoint_pos11" rgba="1 0 0 1" pos="-0.15032974  0.02426264 -0.05391328" /><site name="target_keypoint_pos0" rgba="0.8 0.8 0 1" pos="-0.18354311 -0.02265465 -0.11307443" /><site name="target_keypoint_pos1" rgba="0.8 0.8 0 1" pos="-0.13834541 -0.01406394 -0.06279787" /><site name="target_keypoint_pos2" rgba="0.8 0.8 0 1" pos="-0.13765854  0.02725918 -0.06636332" /><site name="target_keypoint_pos3" rgba="0.8 0.8 0 1" pos="-0.14398741 -0.0149401  -0.09019207" /><site name="target_keypoint_pos4" rgba="0.8 0.8 0 1" pos="-0.16788289  0.01710014 -0.09497554" /><site name="target_keypoint_pos5" rgba="0.8 0.8 0 1" pos="-0.14629366 -0.01755173 -0.11824732" /><site name="target_keypoint_pos6" rgba="0.8 0.8 0 1" pos="-0.16039533  0.01481318 -0.1221482 " /><site name="target_keypoint_pos7" rgba="0.8 0.8 0 1" pos="-0.15228533 -0.02186596 -0.14515703" /><site name="target_keypoint_pos8" rgba="0.8 0.8 0 1" pos="-0.16036829  0.00539792 -0.14808066" /><site name="target_keypoint_pos9" rgba="0.8 0.8 0 1" pos="-0.18425727 -0.00769176 -0.07666892" /><site name="target_keypoint_pos10" rgba="0.8 0.8 0 1" pos="-0.17049306  0.00679149 -0.06801103" /><site name="target_keypoint_pos11" rgba="0.8 0.8 0 1" pos="-0.14410727  0.02299412 -0.05691018" /><body name="__mocap__" mocap="true" pos=" 0.    -0.055  0.002" quat=" 0.         -0.70710678  0.70710678  0.        "><geom type="box" size="0.02 0.02 0.04" group="2" rgba="1 0.7 0 0.8" contype="0" conaffinity="0" /></body></worldbody>


    
    </mujoco>