<mujoco model="panda-arm">
  <option integrator="implicit" />

  <actuator>
    <position name="actuator1" joint="joint1" kp="3500" ctrlrange="-2.8973 2.8973" forcerange="-87 87" />
    <position name="actuator2" joint="joint2" ctrlrange="-1.7628 1.7628" kp="3500" forcerange="-87 87" />
    <position name="actuator3" joint="joint3" kp="3500" ctrlrange="-2.8973 2.8973" forcerange="-87 87" />
    <position name="actuator4" joint="joint4" ctrlrange="-3.0718 -0.0698" kp="3500" forcerange="-87 87" />
    <position name="actuator5" joint="joint5" forcerange="-12 12" kp="3500" ctrlrange="-2.8973 2.8973" />
    <position name="actuator6" joint="joint6" forcerange="-12 12" ctrlrange="-0.0175 3.7525" kp="3500" />
    <position name="actuator7" joint="joint7" forcerange="-12 12" kp="3500" ctrlrange="-2.8973 2.8973" />
  <position name="a_th_rot" joint="palm_to_th_proximal" ctrlrange="-1.571 0" kp="200" forcerange="-50 50" />
        <position name="a_th_bend" joint="th_proximal_to_th_inter" ctrlrange="0 1.571" kp="200" forcerange="-50 50" />
        <position name="a_if_bend" joint="palm_to_if_proximal" ctrlrange="-1.571 0" kp="200" forcerange="-50 50" />
        <position name="a_mf_bend" joint="palm_to_mf_proximal" ctrlrange="-1.571 0" kp="200" forcerange="-50 50" />
        <position name="a_rf_lf_bend" joint="palm_to_rf_proximal" ctrlrange="-1.571 0" kp="200" forcerange="-50 50" />
    </actuator>

  <asset>
    <mesh file="vive_tracker_0000.stl" name="vive_tracker_vive_tracker" />
    <material name="vive_tracker_htc_vive_blue" specular="0.5" shininess="0.25" rgba="0.698 0.89 1 1" />
        <material name="panda_white" rgba="1 1 1 1" specular="0.5" shininess="0.25" />
    <material name="panda_off_white" rgba="0.901961 0.921569 0.929412 1" specular="0.5" shininess="0.25" />
    <material name="panda_black" rgba="0.25 0.25 0.25 1" specular="0.5" shininess="0.25" />
    <material name="panda_green" rgba="0 1 0 1" specular="0.5" shininess="0.25" />
    <material name="panda_light_blue" rgba="0.039216 0.541176 0.780392 1" specular="0.5" shininess="0.25" />

    
    <mesh name="panda_link0_c" file="link0_0000.stl" />
    <mesh name="panda_link1_c" file="link1_0000.stl" />
    <mesh name="panda_link2_c" file="link2_0000.stl" />
    <mesh name="panda_link3_c" file="link3_0000.stl" />
    <mesh name="panda_link4_c" file="link4_0000.stl" />
    <mesh name="panda_link5_c0" file="link5_collision_0_0000.obj" />
    <mesh name="panda_link5_c1" file="link5_collision_1_0000.obj" />
    <mesh name="panda_link5_c2" file="link5_collision_2_0000.obj" />
    <mesh name="panda_link6_c" file="link6_0000.stl" />
    <mesh name="panda_link7_c" file="link7_0000.stl" />

    
    <mesh file="link0_0_0000.obj" name="panda_link0_0" />
    <mesh file="link0_1_0000.obj" name="panda_link0_1" />
    <mesh file="link0_2_0000.obj" name="panda_link0_2" />
    <mesh file="link0_3_0000.obj" name="panda_link0_3" />
    <mesh file="link0_4_0000.obj" name="panda_link0_4" />
    <mesh file="link0_5_0000.obj" name="panda_link0_5" />
    <mesh file="link0_7_0000.obj" name="panda_link0_7" />
    <mesh file="link0_8_0000.obj" name="panda_link0_8" />
    <mesh file="link0_9_0000.obj" name="panda_link0_9" />
    <mesh file="link0_10_0000.obj" name="panda_link0_10" />
    <mesh file="link0_11_0000.obj" name="panda_link0_11" />
    <mesh file="link1_0000.obj" name="panda_link1" />
    <mesh file="link2_0000.obj" name="panda_link2" />
    <mesh file="link3_0_0000.obj" name="panda_link3_0" />
    <mesh file="link3_1_0000.obj" name="panda_link3_1" />
    <mesh file="link3_2_0000.obj" name="panda_link3_2" />
    <mesh file="link3_3_0000.obj" name="panda_link3_3" />
    <mesh file="link4_0_0000.obj" name="panda_link4_0" />
    <mesh file="link4_1_0000.obj" name="panda_link4_1" />
    <mesh file="link4_2_0000.obj" name="panda_link4_2" />
    <mesh file="link4_3_0000.obj" name="panda_link4_3" />
    <mesh file="link5_0_0000.obj" name="panda_link5_0" />
    <mesh file="link5_1_0000.obj" name="panda_link5_1" />
    <mesh file="link5_2_0000.obj" name="panda_link5_2" />
    <mesh file="link6_0_0000.obj" name="panda_link6_0" />
    <mesh file="link6_1_0000.obj" name="panda_link6_1" />
    <mesh file="link6_2_0000.obj" name="panda_link6_2" />
    <mesh file="link6_3_0000.obj" name="panda_link6_3" />
    <mesh file="link6_4_0000.obj" name="panda_link6_4" />
    <mesh file="link6_5_0000.obj" name="panda_link6_5" />
    <mesh file="link6_6_0000.obj" name="panda_link6_6" />
    <mesh file="link6_7_0000.obj" name="panda_link6_7" />
    <mesh file="link6_8_0000.obj" name="panda_link6_8" />
    <mesh file="link6_9_0000.obj" name="panda_link6_9" />
    <mesh file="link6_10_0000.obj" name="panda_link6_10" />
    <mesh file="link6_11_0000.obj" name="panda_link6_11" />
    <mesh file="link6_12_0000.obj" name="panda_link6_12" />
    <mesh file="link6_13_0000.obj" name="panda_link6_13" />
    <mesh file="link6_14_0000.obj" name="panda_link6_14" />
    <mesh file="link6_15_0000.obj" name="panda_link6_15" />
    <mesh file="link6_16_0000.obj" name="panda_link6_16" />
    <mesh file="link7_0_0000.obj" name="panda_link7_0" />
    <mesh file="link7_1_0000.obj" name="panda_link7_1" />
    <mesh file="link7_2_0000.obj" name="panda_link7_2" />
    <mesh file="link7_3_0000.obj" name="panda_link7_3" />
    <mesh file="link7_4_0000.obj" name="panda_link7_4" />
    <mesh file="link7_5_0000.obj" name="panda_link7_5" />
    <mesh file="link7_6_0000.obj" name="panda_link7_6" />
    <mesh file="link7_7_0000.obj" name="panda_link7_7" />
  <material name="right_schunk_sih_hand_black" specular="0.5" shininess="0.25" rgba="0.16355 0.16355 0.16355 1" />
        <material name="right_schunk_sih_hand_gray" specular="0.0" shininess="0.25" rgba="0.80848 0.80848 0.80848 1" />
        <material name="right_schunk_sih_hand_brushed_metal" specular="0" shininess="0.25" rgba="0.863 0.863 0.863 1" />
        <material name="right_schunk_sih_hand_screws" specular="0" shininess="0.25" rgba="0.7 0.7 0.7 1" />
        <material name="right_schunk_sih_hand_shiny_metal" specular="0" shininess="0.85" rgba="0.91 0.91 0.98 1" />
        <material name="right_schunk_sih_hand_gold_metal" specular="0" shininess="0.25" rgba="0.917 0.882 0.761 1" />

        <mesh file="palm_0000.stl" name="right_schunk_sih_hand_palm" scale="0.001 0.001 0.001" />
        <mesh file="if_proximal_0000.stl" name="right_schunk_sih_hand_if_proximal" scale="0.001 0.001 0.001" />
        <mesh file="if_distal_0000.stl" name="right_schunk_sih_hand_if_distal" scale="0.001 0.001 0.001" />
        <mesh file="mf_proximal_0000.stl" name="right_schunk_sih_hand_mf_proximal" scale="0.001 0.001 0.001" />
        <mesh file="mf_distal_0000.stl" name="right_schunk_sih_hand_mf_distal" scale="0.001 0.001 0.001" />
        <mesh file="rf_proximal_0000.stl" name="right_schunk_sih_hand_rf_proximal" scale="0.001 0.001 0.001" />
        <mesh file="rf_distal_0000.stl" name="right_schunk_sih_hand_rf_distal" scale="0.001 0.001 0.001" />
        <mesh file="lf_proximal_0000.stl" name="right_schunk_sih_hand_lf_proximal" scale="0.001 0.001 0.001" />
        <mesh file="lf_distal_0000.stl" name="right_schunk_sih_hand_lf_distal" scale="0.001 0.001 0.001" />
        <mesh file="th_proximal_0000.stl" name="right_schunk_sih_hand_th_proximal" scale="0.001 0.001 0.001" />
        <mesh file="th_inter_0000.stl" name="right_schunk_sih_hand_th_inter" scale="0.001 0.001 0.001" />
        <mesh file="th_inter_cvx_0000.stl" name="right_schunk_sih_hand_th_inter_cvx" scale="0.001 0.001 0.001" />
        <mesh file="th_distal_0000.stl" name="right_schunk_sih_hand_th_distal" scale="0.001 0.001 0.001" />

        <mesh file="palm_axes_0000.stl" name="right_schunk_sih_hand_palm_axes" scale="0.001 0.001 0.001" />
        <mesh file="palm_back_base_0000.stl" name="right_schunk_sih_hand_palm_back_base" scale="0.001 0.001 0.001" />
        <mesh file="palm_back_plate_0000.stl" name="right_schunk_sih_hand_palm_back_plate" scale="0.001 0.001 0.001" />
        <mesh file="palm_connector_0000.stl" name="right_schunk_sih_hand_palm_connector" scale="0.001 0.001 0.001" />
        <mesh file="palm_flange_screws_0000.stl" name="right_schunk_sih_hand_palm_flange_screws" scale="0.001 0.001 0.001" />
        <mesh file="palm_flange_0000.stl" name="right_schunk_sih_hand_palm_flange" scale="0.001 0.001 0.001" />
        <mesh file="palm_front_base_0000.stl" name="right_schunk_sih_hand_palm_front_base" scale="0.001 0.001 0.001" />
        <mesh file="palm_front_plate_0000.stl" name="right_schunk_sih_hand_palm_front_plate" scale="0.001 0.001 0.001" />
        <mesh file="palm_pins_0000.stl" name="right_schunk_sih_hand_palm_pins" scale="0.001 0.001 0.001" />
        <mesh file="palm_rolls_0000.stl" name="right_schunk_sih_hand_palm_rolls" scale="0.001 0.001 0.001" />
        <mesh file="palm_springs_0000.stl" name="right_schunk_sih_hand_palm_springs" scale="0.001 0.001 0.001" />
        <mesh file="palm_thumb_base_0000.stl" name="right_schunk_sih_hand_palm_thumb_base" scale="0.001 0.001 0.001" />

        <mesh file="if_distal_top_0000.stl" name="right_schunk_sih_hand_if_distal_top" scale="0.001 0.001 0.001" />
        <mesh file="if_distal_bottom_0000.stl" name="right_schunk_sih_hand_if_distal_bottom" scale="0.001 0.001 0.001" />
        <mesh file="if_distal_nail_0000.stl" name="right_schunk_sih_hand_if_distal_nail" scale="0.001 0.001 0.001" />
        <mesh file="if_distal_axis_0000.stl" name="right_schunk_sih_hand_if_distal_axis" scale="0.001 0.001 0.001" />
        <mesh file="if_distal_spring_0000.stl" name="right_schunk_sih_hand_if_distal_spring" scale="0.001 0.001 0.001" />
        <mesh file="if_proximal_back_plate_0000.stl" name="right_schunk_sih_hand_if_proximal_back_plate" scale="0.001 0.001 0.001" />
        <mesh file="if_proximal_base_0000.stl" name="right_schunk_sih_hand_if_proximal_base" scale="0.001 0.001 0.001" />
        <mesh file="if_proximal_front_plate_0000.stl" name="right_schunk_sih_hand_if_proximal_front_plate" scale="0.001 0.001 0.001" />
        <mesh file="if_proximal_roll_0000.stl" name="right_schunk_sih_hand_if_proximal_roll" scale="0.001 0.001 0.001" />
        <mesh file="if_proximal_screws_0000.stl" name="right_schunk_sih_hand_if_proximal_screws" scale="0.001 0.001 0.001" />

        <mesh file="mf_distal_top_0000.stl" name="right_schunk_sih_hand_mf_distal_top" scale="0.001 0.001 0.001" />
        <mesh file="mf_distal_bottom_0000.stl" name="right_schunk_sih_hand_mf_distal_bottom" scale="0.001 0.001 0.001" />
        <mesh file="mf_distal_nail_0000.stl" name="right_schunk_sih_hand_mf_distal_nail" scale="0.001 0.001 0.001" />
        <mesh file="mf_distal_axis_0000.stl" name="right_schunk_sih_hand_mf_distal_axis" scale="0.001 0.001 0.001" />
        <mesh file="mf_distal_spring_0000.stl" name="right_schunk_sih_hand_mf_distal_spring" scale="0.001 0.001 0.001" />
        <mesh file="mf_proximal_back_plate_0000.stl" name="right_schunk_sih_hand_mf_proximal_back_plate" scale="0.001 0.001 0.001" />
        <mesh file="mf_proximal_base_0000.stl" name="right_schunk_sih_hand_mf_proximal_base" scale="0.001 0.001 0.001" />
        <mesh file="mf_proximal_front_plate_0000.stl" name="right_schunk_sih_hand_mf_proximal_front_plate" scale="0.001 0.001 0.001" />
        <mesh file="mf_proximal_roll_0000.stl" name="right_schunk_sih_hand_mf_proximal_roll" scale="0.001 0.001 0.001" />
        <mesh file="mf_proximal_screws_0000.stl" name="right_schunk_sih_hand_mf_proximal_screws" scale="0.001 0.001 0.001" />

        <mesh file="rf_distal_top_0000.stl" name="right_schunk_sih_hand_rf_distal_top" scale="0.001 0.001 0.001" />
        <mesh file="rf_distal_bottom_0000.stl" name="right_schunk_sih_hand_rf_distal_bottom" scale="0.001 0.001 0.001" />
        <mesh file="rf_distal_nail_0000.stl" name="right_schunk_sih_hand_rf_distal_nail" scale="0.001 0.001 0.001" />
        <mesh file="rf_distal_axis_0000.stl" name="right_schunk_sih_hand_rf_distal_axis" scale="0.001 0.001 0.001" />
        <mesh file="rf_distal_spring_0000.stl" name="right_schunk_sih_hand_rf_distal_spring" scale="0.001 0.001 0.001" />
        <mesh file="rf_proximal_back_plate_0000.stl" name="right_schunk_sih_hand_rf_proximal_back_plate" scale="0.001 0.001 0.001" />
        <mesh file="rf_proximal_base_0000.stl" name="right_schunk_sih_hand_rf_proximal_base" scale="0.001 0.001 0.001" />
        <mesh file="rf_proximal_front_plate_0000.stl" name="right_schunk_sih_hand_rf_proximal_front_plate" scale="0.001 0.001 0.001" />
        <mesh file="rf_proximal_roll_0000.stl" name="right_schunk_sih_hand_rf_proximal_roll" scale="0.001 0.001 0.001" />
        <mesh file="rf_proximal_screws_0000.stl" name="right_schunk_sih_hand_rf_proximal_screws" scale="0.001 0.001 0.001" />

        <mesh file="lf_distal_top_0000.stl" name="right_schunk_sih_hand_lf_distal_top" scale="0.001 0.001 0.001" />
        <mesh file="lf_distal_bottom_0000.stl" name="right_schunk_sih_hand_lf_distal_bottom" scale="0.001 0.001 0.001" />
        <mesh file="lf_distal_nail_0000.stl" name="right_schunk_sih_hand_lf_distal_nail" scale="0.001 0.001 0.001" />
        <mesh file="lf_proximal_axis_0000.stl" name="right_schunk_sih_hand_lf_proximal_axis" scale="0.001 0.001 0.001" />
        <mesh file="lf_proximal_back_plate_0000.stl" name="right_schunk_sih_hand_lf_proximal_back_plate" scale="0.001 0.001 0.001" />
        <mesh file="lf_proximal_base_0000.stl" name="right_schunk_sih_hand_lf_proximal_base" scale="0.001 0.001 0.001" />
        <mesh file="lf_proximal_front_plate_0000.stl" name="right_schunk_sih_hand_lf_proximal_front_plate" scale="0.001 0.001 0.001" />
        <mesh file="lf_proximal_roll_0000.stl" name="right_schunk_sih_hand_lf_proximal_roll" scale="0.001 0.001 0.001" />
        <mesh file="lf_proximal_screws_0000.stl" name="right_schunk_sih_hand_lf_proximal_screws" scale="0.001 0.001 0.001" />

        <mesh file="th_distal_top_0000.stl" name="right_schunk_sih_hand_th_distal_top" scale="0.001 0.001 0.001" />
        <mesh file="th_distal_bottom_0000.stl" name="right_schunk_sih_hand_th_distal_bottom" scale="0.001 0.001 0.001" />
        <mesh file="th_distal_nail_0000.stl" name="right_schunk_sih_hand_th_distal_nail" scale="0.001 0.001 0.001" />
        <mesh file="th_distal_axis_0000.stl" name="right_schunk_sih_hand_th_distal_axis" scale="0.001 0.001 0.001" />

        <mesh file="th_inter_back_plate_0000.stl" name="right_schunk_sih_hand_th_inter_back_plate" scale="0.001 0.001 0.001" />
        <mesh file="th_inter_base_0000.stl" name="right_schunk_sih_hand_th_inter_base" scale="0.001 0.001 0.001" />
        <mesh file="th_inter_front_plate_0000.stl" name="right_schunk_sih_hand_th_inter_front_plate" scale="0.001 0.001 0.001" />
        <mesh file="th_inter_roll_0000.stl" name="right_schunk_sih_hand_th_inter_roll" scale="0.001 0.001 0.001" />
        <mesh file="th_inter_screws_0000.stl" name="right_schunk_sih_hand_th_inter_screws" scale="0.001 0.001 0.001" />
        <mesh file="th_inter_spring_0000.stl" name="right_schunk_sih_hand_th_inter_spring" scale="0.001 0.001 0.001" />

        <mesh file="th_proximal_axis_0000.stl" name="right_schunk_sih_hand_th_proximal_axis" scale="0.001 0.001 0.001" />
        <mesh file="th_proximal_base_0000.stl" name="right_schunk_sih_hand_th_proximal_base" scale="0.001 0.001 0.001" />
        <mesh file="th_proximal_guides_0000.stl" name="right_schunk_sih_hand_th_proximal_guides" scale="0.001 0.001 0.001" />
        <mesh file="th_proximal_roll_0000.stl" name="right_schunk_sih_hand_th_proximal_roll" scale="0.001 0.001 0.001" />
        <mesh file="th_proximal_screws_0000.stl" name="right_schunk_sih_hand_th_proximal_screws" scale="0.001 0.001 0.001" />
        <mesh file="th_proximal_spring_0000.stl" name="right_schunk_sih_hand_th_proximal_spring" scale="0.001 0.001 0.001" />

    </asset>

  <compiler angle="radian" meshdir=".dexterity_xml_model_meshes" autolimits="true" />

  <contact><exclude body1="if_proximal" body2="if_distal" />
        <exclude body1="mf_proximal" body2="mf_distal" />
        <exclude body1="rf_proximal" body2="rf_distal" />
        <exclude body1="lf_proximal" body2="lf_distal" />
        <exclude body1="th_proximal" body2="th_distal" />

        <exclude body1="palm" body2="if_proximal" />
        <exclude body1="palm" body2="mf_proximal" />
        <exclude body1="palm" body2="rf_proximal" />
        <exclude body1="palm" body2="lf_proximal" />
        <exclude body1="palm" body2="th_proximal" />
    </contact><default /><equality><joint name="th_bend_equality" joint1="th_proximal_to_th_inter" joint2="th_inter_to_th_distal" polycoef="0 1 0 0 0" />
        <joint name="if_bend_equality" joint1="palm_to_if_proximal" joint2="if_proximal_to_if_distal" polycoef="0 1 0 0 0" />
        <joint name="mf_bend_equality" joint1="palm_to_mf_proximal" joint2="mf_proximal_to_mf_distal" polycoef="0 1 0 0 0" />
        <joint name="rf_bend_equality" joint1="palm_to_rf_proximal" joint2="rf_proximal_to_rf_distal" polycoef="0 1 0 0 0" />
        <joint name="rf_lf_equality1" joint1="palm_to_rf_proximal" joint2="palm_to_lf_proximal" polycoef="0 1 0 0 0" />
        <joint name="rf_lf_equality2" joint1="palm_to_rf_proximal" joint2="lf_proximal_to_lf_distal" polycoef="0 1 0 0 0" />
    </equality><keyframe>
    <key name="home" qpos="0 0 0 -1.57079 0 1.57079 -0.7853 0 0 0 0 0 0 0 0 0 0 0" ctrl="0 0 0 -1.57079 0 1.57079 -0.7853 0 0 0 0 0" />
    <key name="initial" qpos="0 -0.5 0 -2.07079 0 1.57079 -0.707 0 0 0 0 0 0 0 0 0 0 0" ctrl="0 -0.5 0 -2.07079 0 1.57079 -0.707 0 0 0 0 0" />
  </keyframe>
<sensor /><worldbody>
    <light name="top" pos="0 0 2" mode="trackcom" />
    <body name="link0">
      <inertial mass="0.629769" pos="-0.041018 -0.00014 0.049974" fullinertia="0.00315 0.00388 0.004285 8.2904e-7 0.00015 8.2299e-6" />
      <geom mesh="panda_link0_0" material="panda_off_white" type="mesh" contype="0" conaffinity="0" group="2" />
      <geom mesh="panda_link0_1" material="panda_black" type="mesh" contype="0" conaffinity="0" group="2" />
      <geom mesh="panda_link0_2" material="panda_off_white" type="mesh" contype="0" conaffinity="0" group="2" />
      <geom mesh="panda_link0_3" material="panda_black" type="mesh" contype="0" conaffinity="0" group="2" />
      <geom mesh="panda_link0_4" material="panda_off_white" type="mesh" contype="0" conaffinity="0" group="2" />
      <geom mesh="panda_link0_5" material="panda_black" type="mesh" contype="0" conaffinity="0" group="2" />
      <geom mesh="panda_link0_7" material="panda_white" type="mesh" contype="0" conaffinity="0" group="2" />
      <geom mesh="panda_link0_8" material="panda_white" type="mesh" contype="0" conaffinity="0" group="2" />
      <geom mesh="panda_link0_9" material="panda_black" type="mesh" contype="0" conaffinity="0" group="2" />
      <geom mesh="panda_link0_10" material="panda_off_white" type="mesh" contype="0" conaffinity="0" group="2" />
      <geom mesh="panda_link0_11" material="panda_white" type="mesh" contype="0" conaffinity="0" group="2" />
      <geom mesh="panda_link0_c" type="mesh" group="3" />
      <body name="link1" pos="0 0 0.333">
        <inertial mass="4.970684" pos="0.003875 0.002081 -0.04762" fullinertia="0.70337 0.70661 0.0091170 -0.00013900 0.0067720 0.019169" />
        <joint name="joint1" range="-0.7854 0.7854" armature="0.1" damping="200" axis="0 0 1" limited="true" />
        <geom material="panda_white" mesh="panda_link1" type="mesh" contype="0" conaffinity="0" group="2" />
        <geom mesh="panda_link1_c" type="mesh" group="3" />
        <body name="link2" quat="1 -1 0 0">
          <inertial mass="0.646926" pos="-0.003141 -0.02872 0.003495" fullinertia="0.0079620 2.8110e-2 2.5995e-2 -3.925e-3 1.0254e-2 7.04e-4" />
          <joint name="joint2" range="-1.7628 1.7628" armature="0.1" damping="200" axis="0 0 1" limited="true" />
          <geom material="panda_white" mesh="panda_link2" type="mesh" contype="0" conaffinity="0" group="2" />
          <geom mesh="panda_link2_c" type="mesh" group="3" />
          <body name="link3" pos="0 -0.316 0" quat="1 1 0 0">
            <joint name="joint3" range="-0.7854 0.7854" armature="0.1" damping="200" axis="0 0 1" limited="true" />
            <inertial mass="3.228604" pos="2.7518e-2 3.9252e-2 -6.6502e-2" fullinertia="3.7242e-2 3.6155e-2 1.083e-2 -4.761e-3 -1.1396e-2 -1.2805e-2" />
            <geom mesh="panda_link3_0" material="panda_white" type="mesh" contype="0" conaffinity="0" group="2" />
            <geom mesh="panda_link3_1" material="panda_white" type="mesh" contype="0" conaffinity="0" group="2" />
            <geom mesh="panda_link3_2" material="panda_white" type="mesh" contype="0" conaffinity="0" group="2" />
            <geom mesh="panda_link3_3" material="panda_black" type="mesh" contype="0" conaffinity="0" group="2" />
            <geom mesh="panda_link3_c" type="mesh" group="3" />
            <body name="link4" pos="0.0825 0 0" quat="1 1 0 0">
              <inertial mass="3.587895" pos="-5.317e-2 1.04419e-1 2.7454e-2" fullinertia="2.5853e-2 1.9552e-2 2.8323e-2 7.796e-3 -1.332e-3 8.641e-3" />
              <joint name="joint4" range="-3.0718 -0.8" armature="0.1" damping="200" axis="0 0 1" limited="true" />
              <geom mesh="panda_link4_0" material="panda_white" type="mesh" contype="0" conaffinity="0" group="2" />
              <geom mesh="panda_link4_1" material="panda_white" type="mesh" contype="0" conaffinity="0" group="2" />
              <geom mesh="panda_link4_2" material="panda_black" type="mesh" contype="0" conaffinity="0" group="2" />
              <geom mesh="panda_link4_3" material="panda_white" type="mesh" contype="0" conaffinity="0" group="2" />
              <geom mesh="panda_link4_c" type="mesh" group="3" />
              <body name="link5" pos="-0.0825 0.384 0" quat="1 -1 0 0">
                <inertial mass="1.225946" pos="-1.1953e-2 4.1065e-2 -3.8437e-2" fullinertia="3.5549e-2 2.9474e-2 8.627e-3 -2.117e-3 -4.037e-3 2.29e-4" />
                <joint name="joint5" armature="0.1" damping="200" axis="0 0 1" range="-2.8973 2.8973" limited="true" />
                <geom mesh="panda_link5_0" material="panda_black" type="mesh" contype="0" conaffinity="0" group="2" />
                <geom mesh="panda_link5_1" material="panda_white" type="mesh" contype="0" conaffinity="0" group="2" />
                <geom mesh="panda_link5_2" material="panda_white" type="mesh" contype="0" conaffinity="0" group="2" />
                <geom mesh="panda_link5_c0" type="mesh" group="3" />
                <geom mesh="panda_link5_c1" type="mesh" group="3" />
                <geom mesh="panda_link5_c2" type="mesh" group="3" />
                <body name="link6" quat="1 1 0 0">
                  <inertial mass="1.666555" pos="6.0149e-2 -1.4117e-2 -1.0517e-2" fullinertia="1.964e-3 4.354e-3 5.433e-3 1.09e-4 -1.158e-3 3.41e-4" />
                  <joint name="joint6" range="-0.0175 3.1415" armature="0.1" damping="200" axis="0 0 1" limited="true" />
                  <geom mesh="panda_link6_0" material="panda_off_white" type="mesh" contype="0" conaffinity="0" group="2" />
                  <geom mesh="panda_link6_1" material="panda_white" type="mesh" contype="0" conaffinity="0" group="2" />
                  <geom mesh="panda_link6_2" material="panda_black" type="mesh" contype="0" conaffinity="0" group="2" />
                  <geom mesh="panda_link6_3" material="panda_white" type="mesh" contype="0" conaffinity="0" group="2" />
                  <geom mesh="panda_link6_4" material="panda_white" type="mesh" contype="0" conaffinity="0" group="2" />
                  <geom mesh="panda_link6_5" material="panda_white" type="mesh" contype="0" conaffinity="0" group="2" />
                  <geom mesh="panda_link6_6" material="panda_white" type="mesh" contype="0" conaffinity="0" group="2" />
                  <geom mesh="panda_link6_7" material="panda_light_blue" type="mesh" contype="0" conaffinity="0" group="2" />
                  <geom mesh="panda_link6_8" material="panda_light_blue" type="mesh" contype="0" conaffinity="0" group="2" />
                  <geom mesh="panda_link6_9" material="panda_black" type="mesh" contype="0" conaffinity="0" group="2" />
                  <geom mesh="panda_link6_10" material="panda_black" type="mesh" contype="0" conaffinity="0" group="2" />
                  <geom mesh="panda_link6_11" material="panda_white" type="mesh" contype="0" conaffinity="0" group="2" />
                  <geom mesh="panda_link6_12" material="panda_green" type="mesh" contype="0" conaffinity="0" group="2" />
                  <geom mesh="panda_link6_13" material="panda_white" type="mesh" contype="0" conaffinity="0" group="2" />
                  <geom mesh="panda_link6_14" material="panda_black" type="mesh" contype="0" conaffinity="0" group="2" />
                  <geom mesh="panda_link6_15" material="panda_black" type="mesh" contype="0" conaffinity="0" group="2" />
                  <geom mesh="panda_link6_16" material="panda_white" type="mesh" contype="0" conaffinity="0" group="2" />
                  <geom mesh="panda_link6_c" type="mesh" group="3" />
                  <body name="link7" pos="0.088 0 0" quat="1 1 0 0">
                    <inertial mass="7.35522e-01" pos="1.0517e-2 -4.252e-3 6.1597e-2" fullinertia="1.2516e-2 1.0027e-2 4.815e-3 -4.28e-4 -1.196e-3 -7.41e-4" />
                    <joint name="joint7" armature="0.1" damping="200" axis="0 0 1" range="-2.8973 2.8973" limited="true" />
                    <geom mesh="panda_link7_0" material="panda_white" type="mesh" contype="0" conaffinity="0" group="2" />
                    <geom mesh="panda_link7_1" material="panda_black" type="mesh" contype="0" conaffinity="0" group="2" />
                    <geom mesh="panda_link7_2" material="panda_black" type="mesh" contype="0" conaffinity="0" group="2" />
                    <geom mesh="panda_link7_3" material="panda_black" type="mesh" contype="0" conaffinity="0" group="2" />
                    <geom mesh="panda_link7_4" material="panda_black" type="mesh" contype="0" conaffinity="0" group="2" />
                    <geom mesh="panda_link7_5" material="panda_black" type="mesh" contype="0" conaffinity="0" group="2" />
                    <geom mesh="panda_link7_6" material="panda_black" type="mesh" contype="0" conaffinity="0" group="2" />
                    <geom mesh="panda_link7_7" material="panda_white" type="mesh" contype="0" conaffinity="0" group="2" />
                    <geom mesh="panda_link7_c" type="mesh" group="3" />
                    
                    <site name="right_schunk_sih_hand_attached_here" pos="0 0 0.107" quat="0.3826834 0 0 0.9238795" size="0.001" rgba="0.5 0.5 0.5 0.3" group="4" />
                    
                    
                    
                    <body name="eef_body" pos="0 0 0" quat="0 -0.924 -0.383 0" />
                  <body name="palm" pos="-0.02 -0.02  0.15" quat="0.27059803866686005 0.27059803866686005 0.6532814871628069 0.6532814871628069">
                
                <body name="tracker" quat="-0.5 -0.5 0.5 -0.5" pos=" 0.   -0.04  0.08">
            <geom mesh="vive_tracker_vive_tracker" material="vive_tracker_htc_vive_blue" quat="0.5 0.5 -0.5 -0.5" type="mesh" contype="0" conaffinity="0" group="2" />
        </body>
    <site name="vive_tracker_attached_here" pos="0 -0.04 0.08" quat="0 0 0 -1" />
                <geom type="mesh" mesh="right_schunk_sih_hand_palm_axes" material="right_schunk_sih_hand_shiny_metal" contype="0" conaffinity="0" group="2" solimp="0.5 0.99 0.0001" solref="0.005 1" />
                <geom type="mesh" mesh="right_schunk_sih_hand_palm_back_base" material="right_schunk_sih_hand_black" contype="0" conaffinity="0" group="2" solimp="0.5 0.99 0.0001" solref="0.005 1" />
                <geom type="mesh" mesh="right_schunk_sih_hand_palm_back_plate" material="right_schunk_sih_hand_black" contype="0" conaffinity="0" group="2" solimp="0.5 0.99 0.0001" solref="0.005 1" />
                <geom type="mesh" mesh="right_schunk_sih_hand_palm_connector" material="right_schunk_sih_hand_gold_metal" contype="0" conaffinity="0" group="2" solimp="0.5 0.99 0.0001" solref="0.005 1" />
                <geom type="mesh" mesh="right_schunk_sih_hand_palm_flange_screws" material="right_schunk_sih_hand_screws" contype="0" conaffinity="0" group="2" solimp="0.5 0.99 0.0001" solref="0.005 1" />
                <geom type="mesh" mesh="right_schunk_sih_hand_palm_flange" material="right_schunk_sih_hand_brushed_metal" contype="0" conaffinity="0" group="2" solimp="0.5 0.99 0.0001" solref="0.005 1" />
                <geom type="mesh" mesh="right_schunk_sih_hand_palm_front_base" material="right_schunk_sih_hand_brushed_metal" contype="0" conaffinity="0" group="2" solimp="0.5 0.99 0.0001" solref="0.005 1" />
                <geom type="mesh" mesh="right_schunk_sih_hand_palm_front_plate" material="right_schunk_sih_hand_black" contype="0" conaffinity="0" group="2" solimp="0.5 0.99 0.0001" solref="0.005 1" />
                <geom type="mesh" mesh="right_schunk_sih_hand_palm_pins" material="right_schunk_sih_hand_shiny_metal" contype="0" conaffinity="0" group="2" solimp="0.5 0.99 0.0001" solref="0.005 1" />
                <geom type="mesh" mesh="right_schunk_sih_hand_palm_rolls" material="right_schunk_sih_hand_screws" contype="0" conaffinity="0" group="2" solimp="0.5 0.99 0.0001" solref="0.005 1" />
                <geom type="mesh" mesh="right_schunk_sih_hand_palm_springs" material="right_schunk_sih_hand_screws" contype="0" conaffinity="0" group="2" solimp="0.5 0.99 0.0001" solref="0.005 1" />
                <geom type="mesh" mesh="right_schunk_sih_hand_palm_thumb_base" material="right_schunk_sih_hand_brushed_metal" contype="0" conaffinity="0" group="2" solimp="0.5 0.99 0.0001" solref="0.005 1" />
                <geom type="mesh" mesh="right_schunk_sih_hand_palm" group="3" material="right_schunk_sih_hand_gray" solimp="0.5 0.99 0.0001" solref="0.005 1" />

                
                <site name="keypoint-hand_bodies-palm" pos="0 0.018 0.09" />

                
                <body name="if_proximal" pos="0.0435 0 0.141">
                    <site name="keypoint-hand_bodies-if_proximal" pos="-0.087 0.016 0.022" />
                    <site name="teleop-rh_if_flexion" user="0 -1.571 0 0 0" />
                    
                    <joint name="palm_to_if_proximal" range="-1.571 0" pos="0 0 0" axis="1 0 0" damping="1" armature="0.01" limited="true" />
                    <geom pos="-0.0435 0 -0.141" type="mesh" mesh="right_schunk_sih_hand_if_proximal_back_plate" material="right_schunk_sih_hand_black" contype="0" conaffinity="0" group="2" solimp="0.5 0.99 0.0001" solref="0.005 1" />
                    <geom pos="-0.0435 0 -0.141" type="mesh" mesh="right_schunk_sih_hand_if_proximal_base" material="right_schunk_sih_hand_brushed_metal" contype="0" conaffinity="0" group="2" solimp="0.5 0.99 0.0001" solref="0.005 1" />
                    <geom pos="-0.0435 0 -0.141" type="mesh" mesh="right_schunk_sih_hand_if_proximal_front_plate" material="right_schunk_sih_hand_black" contype="0" conaffinity="0" group="2" solimp="0.5 0.99 0.0001" solref="0.005 1" />
                    <geom pos="-0.0435 0 -0.141" type="mesh" mesh="right_schunk_sih_hand_if_proximal_roll" material="right_schunk_sih_hand_screws" contype="0" conaffinity="0" group="2" solimp="0.5 0.99 0.0001" solref="0.005 1" />
                    <geom pos="-0.0435 0 -0.141" type="mesh" mesh="right_schunk_sih_hand_if_proximal_screws" material="right_schunk_sih_hand_screws" contype="0" conaffinity="0" group="2" solimp="0.5 0.99 0.0001" solref="0.005 1" />
                    <geom pos="-0.0435 0 -0.141" type="mesh" mesh="right_schunk_sih_hand_if_proximal" group="3" material="right_schunk_sih_hand_gray" solimp="0.5 0.99 0.0001" solref="0.005 1" />
                    <body name="if_distal" pos="0 0 0.048">
                        <site name="keypoint-hand_bodies-if_distal" pos="-0.087 0.0175 0.041" />
                        <site name="keypoint-fingertips-if" pos="-0.087 0.0175 0.041" />
                        
                        <joint name="if_proximal_to_if_distal" range="-1.571 0" pos="0 0 0" axis="1 0 0" damping="1" armature="0.01" limited="true" />
                        <geom pos="-0.0435 0 -0.189" type="mesh" mesh="right_schunk_sih_hand_if_distal_top" material="right_schunk_sih_hand_black" contype="0" conaffinity="0" group="2" solimp="0.5 0.99 0.0001" solref="0.005 1" />
                        <geom pos="-0.0435 0 -0.189" type="mesh" mesh="right_schunk_sih_hand_if_distal_bottom" material="right_schunk_sih_hand_brushed_metal" contype="0" conaffinity="0" group="2" solimp="0.5 0.99 0.0001" solref="0.005 1" />
                        <geom pos="-0.0435 0 -0.189" type="mesh" mesh="right_schunk_sih_hand_if_distal_nail" material="right_schunk_sih_hand_black" contype="0" conaffinity="0" group="2" solimp="0.5 0.99 0.0001" solref="0.005 1" />
                        <geom pos="-0.0435 0 -0.189" type="mesh" mesh="right_schunk_sih_hand_if_distal_axis" material="right_schunk_sih_hand_shiny_metal" contype="0" conaffinity="0" group="2" solimp="0.5 0.99 0.0001" solref="0.005 1" />
                        <geom pos="-0.0435 0 -0.189" type="mesh" mesh="right_schunk_sih_hand_if_distal_spring" material="right_schunk_sih_hand_screws" contype="0" conaffinity="0" group="2" solimp="0.5 0.99 0.0001" solref="0.005 1" />
                        <geom pos="-0.0435 0 -0.189" type="mesh" mesh="right_schunk_sih_hand_if_distal" group="3" material="right_schunk_sih_hand_gray" solimp="0.5 0.99 0.0001" solref="0.005 1" />
                    </body>
                </body>

                
                <body name="mf_proximal" pos="0.0187 0 0.141">
                    <site name="keypoint-hand_bodies-mf_proximal" pos="-0.0375 0.016 0.024" />
                    <site name="teleop-rh_mf_flexion" user="0 -1.571 0 0 0" />
                    
                    <joint name="palm_to_mf_proximal" range="-1.571 0" pos="0 0 0" axis="1 0 0" damping="1" armature="0.01" limited="true" />
                    <geom pos="-0.0187 0 -0.141" type="mesh" mesh="right_schunk_sih_hand_mf_proximal_back_plate" material="right_schunk_sih_hand_black" contype="0" conaffinity="0" group="2" solimp="0.5 0.99 0.0001" solref="0.005 1" />
                    <geom pos="-0.0187 0 -0.141" type="mesh" mesh="right_schunk_sih_hand_mf_proximal_base" material="right_schunk_sih_hand_brushed_metal" contype="0" conaffinity="0" group="2" solimp="0.5 0.99 0.0001" solref="0.005 1" />
                    <geom pos="-0.0187 0 -0.141" type="mesh" mesh="right_schunk_sih_hand_mf_proximal_front_plate" material="right_schunk_sih_hand_black" contype="0" conaffinity="0" group="2" solimp="0.5 0.99 0.0001" solref="0.005 1" />
                    <geom pos="-0.0187 0 -0.141" type="mesh" mesh="right_schunk_sih_hand_mf_proximal_roll" material="right_schunk_sih_hand_screws" contype="0" conaffinity="0" group="2" solimp="0.5 0.99 0.0001" solref="0.005 1" />
                    <geom pos="-0.0187 0 -0.141" type="mesh" mesh="right_schunk_sih_hand_mf_proximal_screws" material="right_schunk_sih_hand_screws" contype="0" conaffinity="0" group="2" solimp="0.5 0.99 0.0001" solref="0.005 1" />
                    <geom pos="-0.0187 0 -0.141" type="mesh" mesh="right_schunk_sih_hand_mf_proximal" group="3" material="right_schunk_sih_hand_gray" solimp="0.5 0.99 0.0001" solref="0.005 1" />
                    <body name="mf_distal" pos="0 0 0.0525">
                        <site name="keypoint-hand_bodies-mf_distal" pos="-0.0375 0.0175 0.049" />
                        <site name="keypoint-fingertips-mf" pos="-0.0375 0.0175 0.049" />
                        
                        <joint name="mf_proximal_to_mf_distal" range="-1.571 0" pos="0 0 0" axis="1 0 0" damping="1" armature="0.01" limited="true" />
                        <geom pos="-0.0187 0 -0.1935" type="mesh" mesh="right_schunk_sih_hand_mf_distal_top" material="right_schunk_sih_hand_black" contype="0" conaffinity="0" group="2" solimp="0.5 0.99 0.0001" solref="0.005 1" />
                        <geom pos="-0.0187 0 -0.1935" type="mesh" mesh="right_schunk_sih_hand_mf_distal_bottom" material="right_schunk_sih_hand_brushed_metal" contype="0" conaffinity="0" group="2" solimp="0.5 0.99 0.0001" solref="0.005 1" />
                        <geom pos="-0.0187 0 -0.1935" type="mesh" mesh="right_schunk_sih_hand_mf_distal_nail" material="right_schunk_sih_hand_black" contype="0" conaffinity="0" group="2" solimp="0.5 0.99 0.0001" solref="0.005 1" />
                        <geom pos="-0.0187 0 -0.1935" type="mesh" mesh="right_schunk_sih_hand_mf_distal_axis" material="right_schunk_sih_hand_shiny_metal" contype="0" conaffinity="0" group="2" solimp="0.5 0.99 0.0001" solref="0.005 1" />
                        <geom pos="-0.0187 0 -0.1935" type="mesh" mesh="right_schunk_sih_hand_mf_distal_spring" material="right_schunk_sih_hand_screws" contype="0" conaffinity="0" group="2" solimp="0.5 0.99 0.0001" solref="0.005 1" />
                        <geom pos="-0.0187 0 -0.1935" type="mesh" mesh="right_schunk_sih_hand_mf_distal" group="3" material="right_schunk_sih_hand_gray" solimp="0.5 0.99 0.0001" solref="0.005 1" />
                    </body>
                </body>

                
                <body name="rf_proximal" pos="-0.0069 0 0.134">
                    <site name="keypoint-hand_bodies-rf_proximal" pos="0.014 0.016 0.0215" />
                    <site name="teleop-rh_rf_flexion" user="0 -1.571 0 0 0" />
                    
                    <joint name="palm_to_rf_proximal" range="-1.571 0" pos="0 0 0" axis="1 0 0" damping="1" armature="0.01" limited="true" />
                    <geom pos="0.0069 0 -0.134" type="mesh" mesh="right_schunk_sih_hand_rf_proximal_back_plate" material="right_schunk_sih_hand_black" contype="0" conaffinity="0" group="2" solimp="0.5 0.99 0.0001" solref="0.005 1" />
                    <geom pos="0.0069 0 -0.134" type="mesh" mesh="right_schunk_sih_hand_rf_proximal_base" material="right_schunk_sih_hand_brushed_metal" contype="0" conaffinity="0" group="2" solimp="0.5 0.99 0.0001" solref="0.005 1" />
                    <geom pos="0.0069 0 -0.134" type="mesh" mesh="right_schunk_sih_hand_rf_proximal_front_plate" material="right_schunk_sih_hand_black" contype="0" conaffinity="0" group="2" solimp="0.5 0.99 0.0001" solref="0.005 1" />
                    <geom pos="0.0069 0 -0.134" type="mesh" mesh="right_schunk_sih_hand_rf_proximal_roll" material="right_schunk_sih_hand_screws" contype="0" conaffinity="0" group="2" solimp="0.5 0.99 0.0001" solref="0.005 1" />
                    <geom pos="0.0069 0 -0.134" type="mesh" mesh="right_schunk_sih_hand_rf_proximal_screws" material="right_schunk_sih_hand_screws" contype="0" conaffinity="0" group="2" solimp="0.5 0.99 0.0001" solref="0.005 1" />
                    <geom pos="0.0069 0 -0.134" type="mesh" mesh="right_schunk_sih_hand_rf_proximal" group="3" material="right_schunk_sih_hand_gray" solimp="0.5 0.99 0.0001" solref="0.005 1" />
                    <body name="rf_distal" pos="0 0 0.048">
                        <site name="keypoint-hand_bodies-rf_distal" pos="0.014 0.0175 0.041" />
                        <site name="keypoint-fingertips-rf" pos="0.014 0.0175 0.041" />
                        
                        <joint name="rf_proximal_to_rf_distal" range="-1.571 0" pos="0 0 0" axis="1 0 0" damping="1" armature="0.01" limited="true" />
                        <geom pos="0.0069 0 -0.182" type="mesh" mesh="right_schunk_sih_hand_rf_distal_top" material="right_schunk_sih_hand_black" contype="0" conaffinity="0" group="2" solimp="0.5 0.99 0.0001" solref="0.005 1" />
                        <geom pos="0.0069 0 -0.182" type="mesh" mesh="right_schunk_sih_hand_rf_distal_bottom" material="right_schunk_sih_hand_brushed_metal" contype="0" conaffinity="0" group="2" solimp="0.5 0.99 0.0001" solref="0.005 1" />
                        <geom pos="0.0069 0 -0.182" type="mesh" mesh="right_schunk_sih_hand_rf_distal_nail" material="right_schunk_sih_hand_black" contype="0" conaffinity="0" group="2" solimp="0.5 0.99 0.0001" solref="0.005 1" />
                        <geom pos="0.0069 0 -0.182" type="mesh" mesh="right_schunk_sih_hand_rf_distal_axis" material="right_schunk_sih_hand_shiny_metal" contype="0" conaffinity="0" group="2" solimp="0.5 0.99 0.0001" solref="0.005 1" />
                        <geom pos="0.0069 0 -0.182" type="mesh" mesh="right_schunk_sih_hand_rf_distal_spring" material="right_schunk_sih_hand_screws" contype="0" conaffinity="0" group="2" solimp="0.5 0.99 0.0001" solref="0.005 1" />
                        <geom pos="0.0069 0 -0.182" type="mesh" mesh="right_schunk_sih_hand_rf_distal" group="3" material="right_schunk_sih_hand_gray" solimp="0.5 0.99 0.0001" solref="0.005 1" />
                    </body>
                </body>

                
                <body name="lf_proximal" pos="-0.032 0 0.1254">
                    <site name="keypoint-hand_bodies-lf_proximal" pos="0.064 0.016 0.01685" />
                    
                    <joint name="palm_to_lf_proximal" range="-1.571 0" pos="0 0 0" axis="1 0 0" damping="1" armature="0.01" limited="true" />
                    <geom pos="0.032 0 -0.1254" type="mesh" mesh="right_schunk_sih_hand_lf_proximal_axis" material="right_schunk_sih_hand_shiny_metal" contype="0" conaffinity="0" group="2" solimp="0.5 0.99 0.0001" solref="0.005 1" />
                    <geom pos="0.032 0 -0.1254" type="mesh" mesh="right_schunk_sih_hand_lf_proximal_back_plate" material="right_schunk_sih_hand_black" contype="0" conaffinity="0" group="2" solimp="0.5 0.99 0.0001" solref="0.005 1" />
                    <geom pos="0.032 0 -0.1254" type="mesh" mesh="right_schunk_sih_hand_lf_proximal_base" material="right_schunk_sih_hand_brushed_metal" contype="0" conaffinity="0" group="2" solimp="0.5 0.99 0.0001" solref="0.005 1" />
                    <geom pos="0.032 0 -0.1254" type="mesh" mesh="right_schunk_sih_hand_lf_proximal_front_plate" material="right_schunk_sih_hand_black" contype="0" conaffinity="0" group="2" solimp="0.5 0.99 0.0001" solref="0.005 1" />
                    <geom pos="0.032 0 -0.1254" type="mesh" mesh="right_schunk_sih_hand_lf_proximal_roll" material="right_schunk_sih_hand_screws" contype="0" conaffinity="0" group="2" solimp="0.5 0.99 0.0001" solref="0.005 1" />
                    <geom pos="0.032 0 -0.1254" type="mesh" mesh="right_schunk_sih_hand_lf_proximal_screws" material="right_schunk_sih_hand_screws" contype="0" conaffinity="0" group="2" solimp="0.5 0.99 0.0001" solref="0.005 1" />
                    <geom pos="0.032 0 -0.1254" type="mesh" mesh="right_schunk_sih_hand_lf_proximal" group="3" material="right_schunk_sih_hand_gray" solimp="0.5 0.99 0.0001" solref="0.005 1" />
                    <body name="lf_distal" pos="0 0 0.0401">
                        <site name="keypoint-hand_bodies-lf_distal" pos="0.064 0.0175 0.034" />
                        <site name="keypoint-fingertips-lf" pos="0.064 0.0175 0.034" />
                        
                        <joint name="lf_proximal_to_lf_distal" range="-1.571 0" pos="0 0 0" axis="1 0 0" damping="1" armature="0.01" limited="true" />
                        <geom pos="0.032 0 -0.1655" type="mesh" mesh="right_schunk_sih_hand_lf_distal_top" material="right_schunk_sih_hand_black" contype="0" conaffinity="0" group="2" solimp="0.5 0.99 0.0001" solref="0.005 1" />
                        <geom pos="0.032 0 -0.1655" type="mesh" mesh="right_schunk_sih_hand_lf_distal_bottom" material="right_schunk_sih_hand_brushed_metal" contype="0" conaffinity="0" group="2" solimp="0.5 0.99 0.0001" solref="0.005 1" />
                        <geom pos="0.032 0 -0.1655" type="mesh" mesh="right_schunk_sih_hand_lf_distal_nail" material="right_schunk_sih_hand_black" contype="0" conaffinity="0" group="2" solimp="0.5 0.99 0.0001" solref="0.005 1" />
                        <geom pos="0.032 0 -0.1655" type="mesh" mesh="right_schunk_sih_hand_lf_distal" group="3" material="right_schunk_sih_hand_gray" solimp="0.5 0.99 0.0001" solref="0.005 1" />
                    </body>
                </body>

                
                <body name="th_proximal" pos="-0.034 0.019 0.08">
                    <site name="teleop-rh_th_angle0" user="-1.571 -1 0 0 0" />
                    <site name="keypoint-hand_bodies-th_proximal" pos="-0.0115 0.005 0.011" />
                    
                    <joint name="palm_to_th_proximal" range="-1.571 0" pos="0 0 0" axis="0 0 1" damping="1" armature="0.01" limited="true" />
                    <geom pos="0.034 -0.019 -0.08" type="mesh" mesh="right_schunk_sih_hand_th_proximal_axis" material="right_schunk_sih_hand_shiny_metal" contype="0" conaffinity="0" group="2" solimp="0.5 0.99 0.0001" solref="0.005 1" />
                    <geom pos="0.034 -0.019 -0.08" type="mesh" mesh="right_schunk_sih_hand_th_proximal_base" material="right_schunk_sih_hand_brushed_metal" contype="0" conaffinity="0" group="2" solimp="0.5 0.99 0.0001" solref="0.005 1" />
                    <geom pos="0.034 -0.019 -0.08" type="mesh" mesh="right_schunk_sih_hand_th_proximal_guides" material="right_schunk_sih_hand_black" contype="0" conaffinity="0" group="2" solimp="0.5 0.99 0.0001" solref="0.005 1" />
                    <geom pos="0.034 -0.019 -0.08" type="mesh" mesh="right_schunk_sih_hand_th_proximal_roll" material="right_schunk_sih_hand_screws" contype="0" conaffinity="0" group="2" solimp="0.5 0.99 0.0001" solref="0.005 1" />
                    <geom pos="0.034 -0.019 -0.08" type="mesh" mesh="right_schunk_sih_hand_th_proximal_screws" material="right_schunk_sih_hand_screws" contype="0" conaffinity="0" group="2" solimp="0.5 0.99 0.0001" solref="0.005 1" />
                    <geom pos="0.034 -0.019 -0.08" type="mesh" mesh="right_schunk_sih_hand_th_proximal_spring" material="right_schunk_sih_hand_screws" contype="0" conaffinity="0" group="2" solimp="0.5 0.99 0.0001" solref="0.005 1" />
                    <geom pos="0.034 -0.019 -0.08" type="mesh" mesh="right_schunk_sih_hand_th_proximal" group="3" material="right_schunk_sih_hand_gray" solimp="0.5 0.99 0.0001" solref="0.005 1" />
                    <body name="th_inter" pos="-0.024 0.005 0.001">
                        <site name="teleop-rh_th_flexion" user="0 1.571 0 0 0" />
                        <site name="keypoint-hand_bodies-th_inter" pos="-0.0175 0 0.016" />
                        
                        <joint name="th_proximal_to_th_inter" range="0 1.571" pos="0 0 0" axis="0 1 0" damping="1" armature="0.01" limited="true" />
                        <geom pos="0.058 -0.024 -0.081" type="mesh" mesh="right_schunk_sih_hand_th_inter_back_plate" material="right_schunk_sih_hand_black" contype="0" conaffinity="0" group="2" solimp="0.5 0.99 0.0001" solref="0.005 1" />
                        <geom pos="0.058 -0.024 -0.081" type="mesh" mesh="right_schunk_sih_hand_th_inter_base" material="right_schunk_sih_hand_brushed_metal" contype="0" conaffinity="0" group="2" solimp="0.5 0.99 0.0001" solref="0.005 1" />
                        <geom pos="0.058 -0.024 -0.081" type="mesh" mesh="right_schunk_sih_hand_th_inter_front_plate" material="right_schunk_sih_hand_black" contype="0" conaffinity="0" group="2" solimp="0.5 0.99 0.0001" solref="0.005 1" />
                        <geom pos="0.058 -0.024 -0.081" type="mesh" mesh="right_schunk_sih_hand_th_inter_roll" material="right_schunk_sih_hand_screws" contype="0" conaffinity="0" group="2" solimp="0.5 0.99 0.0001" solref="0.005 1" />
                        <geom pos="0.058 -0.024 -0.081" type="mesh" mesh="right_schunk_sih_hand_th_inter_screws" material="right_schunk_sih_hand_screws" contype="0" conaffinity="0" group="2" solimp="0.5 0.99 0.0001" solref="0.005 1" />
                        <geom pos="0.058 -0.024 -0.081" type="mesh" mesh="right_schunk_sih_hand_th_inter_spring" material="right_schunk_sih_hand_screws" contype="0" conaffinity="0" group="2" solimp="0.5 0.99 0.0001" solref="0.005 1" />
                        <geom pos="0.058 -0.024 -0.081" type="mesh" mesh="right_schunk_sih_hand_th_inter_cvx" group="3" material="right_schunk_sih_hand_gray" solimp="0.5 0.99 0.0001" solref="0.005 1" />
                        <body name="th_distal" pos="-0.0391 0 0">
                            <site name="keypoint-hand_bodies-th_distal" pos="-0.023 0 0.015" />
                            <site name="keypoint-fingertips-th" pos="-0.023 0 0.015" />
                            
                            <joint name="th_inter_to_th_distal" range="0 1.571" pos="0 0 0" axis="0 1 0" damping="1" armature="0.01" limited="true" />
                            <geom pos="0.0971 -0.024 -0.081" type="mesh" mesh="right_schunk_sih_hand_th_distal_top" material="right_schunk_sih_hand_black" contype="0" conaffinity="0" group="2" solimp="0.5 0.99 0.0001" solref="0.005 1" />
                            <geom pos="0.0971 -0.024 -0.081" type="mesh" mesh="right_schunk_sih_hand_th_distal_bottom" material="right_schunk_sih_hand_brushed_metal" contype="0" conaffinity="0" group="2" solimp="0.5 0.99 0.0001" solref="0.005 1" />
                            <geom pos="0.0971 -0.024 -0.081" type="mesh" mesh="right_schunk_sih_hand_th_distal_nail" material="right_schunk_sih_hand_black" contype="0" conaffinity="0" group="2" solimp="0.5 0.99 0.0001" solref="0.005 1" />
                            <geom pos="0.0971 -0.024 -0.081" type="mesh" mesh="right_schunk_sih_hand_th_distal_axis" material="right_schunk_sih_hand_shiny_metal" contype="0" conaffinity="0" group="2" solimp="0.5 0.99 0.0001" solref="0.005 1" />
                            <geom pos="0.0971 -0.024 -0.081" type="mesh" mesh="right_schunk_sih_hand_th_distal" group="3" material="right_schunk_sih_hand_gray" solimp="0.5 0.99 0.0001" solref="0.005 1" />
                        </body>
                    </body>
                </body>
            </body>
    </body>
                </body>
              </body>
            </body>
          </body>
        </body>
      </body>
    </body>
  </worldbody>

  </mujoco>